Workbook

Sheet rows
A1: row_id | B1: Filas
A2: pan_v02_q01_r0001 | B2: PANof001
A3: pan_v02_q01_r0002 | B3: PANof002
A4: pan_v02_q01_r0003 | B4: PANof003
A5: pan_v02_q01_r0004 | B5: PANof004
A6: pan_v02_q01_r0005 | B6: PANof005
A7: pan_v02_q01_r0006 | B7: PANof006
A8: pan_v02_q01_r0007 | B8: PANof007
A9: pan_v02_q01_r0008 | B9: PANof008
A10: pan_v02_q01_r0009 | B10: PANof009
A11: pan_v02_q01_r0010 | B11: PANof010
A12: pan_v02_q01_r0011 | B12: PANof011
... A189: pan_v02_q01_r0188 | B189: PANof188
A190: pan_v02_q01_r0189
A191: pan_v02_q01_r0190 | B191: PANof189
A192: pan_v02_q01_r0191
A193: pan_v02_q01_r0192 | B193: PANof190
A194: pan_v02_q01_r0193 | B194: PANof191
A195: pan_v02_q01_r0194 | B195: PANof192
A196: pan_v02_q01_r0195 | B196: PANof193
A197: pan_v02_q01_r0196
A198: pan_v02_q01_r0197
A199: pan_v02_q02_r0001 | B199: PANuf001
A200: pan_v02_q02_r0002 | B200: PANuf002
A201: pan_v02_q02_r0003 | B201: PANuf003
A202: pan_v02_q02_r0004 | B202: PANuf004
A203: pan_v02_q02_r0005 | B203: PANuf005
A204: pan_v02_q02_r0006 | B204: PANuf006
A205: pan_v02_q02_r0007 | B205: PANuf007
A206: pan_v02_q02_r0008 | B206: PANuf008
A207: pan_v02_q02_r0009 | B207: PANuf009
A208: pan_v02_q02_r0010 | B208: PANuf010
A209: pan_v02_q02_r0011 | B209: PANuf011
A210: pan_v02_q02_r0012 | B210: PANuf012
... A386: pan_v02_q02_r0188 | B386: PANuf188
A387: pan_v02_q02_r0189
A388: pan_v02_q02_r0190 | B388: PANuf189
A389: pan_v02_q02_r0191
A390: pan_v02_q02_r0192 | B390: PANuf190
A391: pan_v02_q02_r0193 | B391: PANuf191
...

Sheet columns
A1: col_id | B1: Columnas
A2: pan_v02_q01_c0001 | B2: PANoc001
A3: pan_v02_q01_c0002 | B3: PANoc002
A4: pan_v02_q01_c0003 | B4: PANoc003
A5: pan_v02_q01_c0004 | B5: PANoc004
A6: pan_v02_q01_c0005 | B6: PANoc005
A7: pan_v02_q01_c0006 | B7: PANoc006
A8: pan_v02_q01_c0007 | B8: PANoc007
A9: pan_v02_q01_c0008 | B9: PANoc008
A10: pan_v02_q01_c0009 | B10: PANoc009
A11: pan_v02_q01_c0010 | B11: PANoc010
A12: pan_v02_q01_c0011 | B12: PANoc011
... A92: pan_v02_q01_c0091 | B92: PANoc091
A93: pan_v02_q01_c0092
A94: pan_v02_q01_c0093
A95: pan_v02_q01_c0094 | B95: PANoc092
A96: pan_v02_q01_c0095 | B96: PANoc093
A97: pan_v02_q01_c0096 | B97: PANoc094
A98: pan_v02_q01_c0097 | B98: PANoc095
A99: pan_v02_q01_c0098 | B99: PANoc096
A100: pan_v02_q01_c0099 | B100: PANoc097
A101: pan_v02_q01_c0100 | B101: PANoc098
A102: pan_v02_q01_c0101 | B102: PANoc099
A103: pan_v02_q01_c0102 | B103: PANoc100
A104: pan_v02_q01_c0103 | B104: PANoc101
A105: pan_v02_q01_c0104 | B105: PANoc102
A106: pan_v02_q01_c0105 | B106: PANoc103
A107: pan_v02_q01_c0106 | B107: PANoc104
A108: pan_v02_q01_c0107
A109: pan_v02_q01_c0108
A110: pan_v02_q02_c0001 | B110: PANuc001
A111: pan_v02_q02_c0002 | B111: PANuc002
A112: pan_v02_q02_c0003 | B112: PANuc003
A113: pan_v02_q02_c0004 | B113: PANuc004
A114: pan_v02_q02_c0005 | B114: PANuc005
A115: pan_v02_q02_c0006 | B115: PANuc006
A116: pan_v02_q02_c0007 | B116: PANuc007
A117: pan_v02_q02_c0008 | B117: PANuc008
A118: pan_v02_q02_c0009 | B118: PANuc009
A119: pan_v02_q02_c0010 | B119: PANuc010
...

Sheet quadrants
A1: quadrant_code | B1: quadrant | C1: target_table | D1: cell_range | E1: excl_rows | F1: excl_cols
A2: q01 | B2: OFERTA DE PRODUCTOS A PRECIOS DE COMPRADOR | C2: Supply | D2: C12:DF208 | E2: 189, 191, 196, 197 | F2: 75,79,90,91,92,93,96,98,103,107,108
A3: q02 | B3: UTILIZACIÓN DE PRODUCTOS A PRECIOS DE COMPRADOR | C3: Use | D3: C12:DG208 | E3: 189, 191, 196, 197 | F3: 75,79,90,91,92,95,99,102,103,108,109
A4: q03 | B4: VALOR AGREGADO BRUTO TOTAL/PIB | C4: Value Added | D4: D210:CQ210 | F4: 75,79,90,91,92

Sheet columnas
A1: Columnas | B1: Código Transacciones | C1: Área transaccional columnas No. | D1: Área transaccional | E1: Transacciones | F1: Correlativo Transacciones Agregadas | G1: Código Transacciones Agregadas | H1: Transacciones Agregadas | I1: Código Clasificación Actividades | J1: Descripción Actividades | K1: CIIU Secciones | L1: CIIU Secciones descripción | M1: CIIU Corto | N1: CIIU English | O1: Correlativo Bioeconomía Actividades | P1: Bioeconomía Actividades
A2: PANoc001 | B2: P11 | C2: =+VLOOKUP(B2,transacciones!$A$1:$I$39,2,FALSE()) -> ATC01 | D2: =+VLOOKUP(B2,transacciones!$A$1:$I$39,3,FALSE()) -> Producción / Consumo intermedio | E2: =+VLOOKUP($B2,transacciones!$A$1:$I$39,4,FALSE()) -> Producción de mercado | F2: =+VLOOKUP(B2,transacciones!$A$2:$I$39,5,FALSE()) -> 1 | G2: =+VLOOKUP(B2,transacciones!$A$2:$I$39,6,FALSE()) -> P1 | H2: =+VLOOKUP(B2,transacciones!$A$1:$I$39,7,FALSE()) -> Producción | I2: 01.1 | J2: Cultivo de cereales, legumbres y semillas oleaginosas | K2: A | L2: =+VLOOKUP(K2,'Correl CIIU'!$A$1:$F$26,2,FALSE()) -> Agricultura, ganadería, silvicultura y pesca | M2: =+VLOOKUP(K2,'Correl CIIU'!$A$1:$F$26,3,FALSE()) -> Agricultura | N2: =+VLOOKUP(K2,'Correl CIIU'!$A$1:$F$26,4,FALSE()) -> Agriculture, forestry and fishing | O2: 1 | P2: =+VLOOKUP(O2,bio!$A$2:$B$4,2,FALSE()) -> Bioeconomía
A3: PANoc002 | B3: P11 | C3: =+VLOOKUP(B3,transacciones!$A$1:$I$39,2,FALSE()) -> ATC01 | D3: =+VLOOKUP(B3,transacciones!$A$1:$I$39,3,FALSE()) -> Producción / Consumo intermedio | E3: =+VLOOKUP($B3,transacciones!$A$1:$I$39,4,FALSE()) -> Producción de mercado | F3: =+VLOOKUP(B3,transacciones!$A$2:$I$39,5,FALSE()) -> 1 | G3: =+VLOOKUP(B3,transacciones!$A$2:$I$39,6,FALSE()) -> P1 | H3: =+VLOOKUP(B3,transacciones!$A$1:$I$39,7,FALSE()) -> Producción | I3: 02.1 | J3: Cultivo de maiz | K3: A | L3: =+VLOOKUP(K3,'Correl CIIU'!$A$1:$F$26,2,FALSE()) -> Agricultura, ganadería, silvicultura y pesca | M3: =+VLOOKUP(K3,'Correl CIIU'!$A$1:$F$26,3,FALSE()) -> Agricultura | N3: =+VLOOKUP(K3,'Correl CIIU'!$A$1:$F$26,4,FALSE()) -> Agriculture, forestry and fishing | O3: 1 | P3: =+VLOOKUP(O3,bio!$A$2:$B$4,2,FALSE()) -> Bioeconomía
A4: PANoc003 | B4: P11 | C4: =+VLOOKUP(B4,transacciones!$A$1:$I$39,2,FALSE()) -> ATC01 | D4: =+VLOOKUP(B4,transacciones!$A$1:$I$39,3,FALSE()) -> Producción / Consumo intermedio | E4: =+VLOOKUP($B4,transacciones!$A$1:$I$39,4,FALSE()) -> Producción de mercado | F4: =+VLOOKUP(B4,transacciones!$A$2:$I$39,5,FALSE()) -> 1 | G4: =+VLOOKUP(B4,transacciones!$A$2:$I$39,6,FALSE()) -> P1 | H4: =+VLOOKUP(B4,transacciones!$A$1:$I$39,7,FALSE()) -> Producción | I4: 03.1 | J4: Cultivo de arroz | K4: A | L4: =+VLOOKUP(K4,'Correl CIIU'!$A$1:$F$26,2,FALSE()) -> Agricultura, ganadería, silvicultura y pesca | M4: =+VLOOKUP(K4,'Correl CIIU'!$A$1:$F$26,3,FALSE()) -> Agricultura | N4: =+VLOOKUP(K4,'Correl CIIU'!$A$1:$F$26,4,FALSE()) -> Agriculture, forestry and fishing | O4: 1 | P4: =+VLOOKUP(O4,bio!$A$2:$B$4,2,FALSE()) -> Bioeconomía
A5: PANoc004 | B5: P11 | C5: =+VLOOKUP(B5,transacciones!$A$1:$I$39,2,FALSE()) -> ATC01 | D5: =+VLOOKUP(B5,transacciones!$A$1:$I$39,3,FALSE()) -> Producción / Consumo intermedio | E5: =+VLOOKUP($B5,transacciones!$A$1:$I$39,4,FALSE()) -> Producción de mercado | F5: =+VLOOKUP(B5,transacciones!$A$2:$I$39,5,FALSE()) -> 1 | G5: =+VLOOKUP(B5,transacciones!$A$2:$I$39,6,FALSE()) -> P1 | H5: =+VLOOKUP(B5,transacciones!$A$1:$I$39,7,FALSE()) -> Producción | I5: 04.1 | J5: Cultivo de vegetales, raíces y tubérculos | K5: A | L5: =+VLOOKUP(K5,'Correl CIIU'!$A$1:$F$26,2,FALSE()) -> Agricultura, ganadería, silvicultura y pesca | M5: =+VLOOKUP(K5,'Correl CIIU'!$A$1:$F$26,3,FALSE()) -> Agricultura | N5: =+VLOOKUP(K5,'Correl CIIU'!$A$1:$F$26,4,FALSE()) -> Agriculture, forestry and fishing | O5: 1 | P5: =+VLOOKUP(O5,bio!$A$2:$B$4,2,FALSE()) -> Bioeconomía
A6: PANoc005 | B6: P11 | C6: =+VLOOKUP(B6,transacciones!$A$1:$I$39,2,FALSE()) -> ATC01 | D6: =+VLOOKUP($B6,transacciones!$A$1:$I$39,4,FALSE()) -> Producción de mercado | E6: =+VLOOKUP($B6,transacciones!$A$1:$I$39,4,FALSE()) -> Producción de mercado | F6: =+VLOOKUP(B6,transacciones!$A$2:$I$39,5,FALSE()) -> 1 | G6: =+VLOOKUP(B6,transacciones!$A$2:$I$39,6,FALSE()) -> P1 | H6: =+VLOOKUP(B6,transacciones!$A$1:$I$39,7,FALSE()) -> Producción | I6: 05.1 | J6: Cultivo de Banano | K6: A | L6: =+VLOOKUP(K6,'Correl CIIU'!$A$1:$F$26,2,FALSE()) -> Agricultura, ganadería, silvicultura y pesca | M6: =+VLOOKUP(K6,'Correl CIIU'!$A$1:$F$26,3,FALSE()) -> Agricultura | N6: =+VLOOKUP(K6,'Correl CIIU'!$A$1:$F$26,4,FALSE()) -> Agriculture, forestry and fishing | O6: 1 | P6: =+VLOOKUP(O6,bio!$A$2:$B$4,2,FALSE()) -> Bioeconomía
A7: PANoc006 | B7: P11 | C7: =+VLOOKUP(B7,transacciones!$A$1:$I$39,2,FALSE()) -> ATC01 | D7: =+VLOOKUP($B7,transacciones!$A$1:$I$39,4,FALSE()) -> Producción de mercado | E7: =+VLOOKUP($B7,transacciones!$A$1:$I$39,4,FALSE()) -> Producción de mercado | F7: =+VLOOKUP(B7,transacciones!$A$2:$I$39,5,FALSE()) -> 1 | G7: =+VLOOKUP(B7,transacciones!$A$2:$I$39,6,FALSE()) -> P1 | H7: =+VLOOKUP(B7,transacciones!$A$1:$I$39,7,FALSE()) -> Producción | I7: 06.1 | J7: Cultivo de otras frutas y nueces | K7: A | L7: =+VLOOKUP(K7,'Correl CIIU'!$A$1:$F$26,2,FALSE()) -> Agricultura, ganadería, silvicultura y pesca | M7: =+VLOOKUP(K7,'Correl CIIU'!$A$1:$F$26,3,FALSE()) -> Agricultura | N7: =+VLOOKUP(K7,'Correl CIIU'!$A$1:$F$26,4,FALSE()) -> Agriculture, forestry and fishing | O7: 1 | P7: =+VLOOKUP(O7,bio!$A$2:$B$4,2,FALSE()) -> Bioeconomía
A8: PANoc007 | B8: P11 | C8: =+VLOOKUP(B8,transacciones!$A$1:$I$39,2,FALSE()) -> ATC01 | D8: =+VLOOKUP($B8,transacciones!$A$1:$I$39,4,FALSE()) -> Producción de mercado | E8: =+VLOOKUP($B8,transacciones!$A$1:$I$39,4,FALSE()) -> Producción de mercado | F8: =+VLOOKUP(B8,transacciones!$A$2:$I$39,5,FALSE()) -> 1 | G8: =+VLOOKUP(B8,transacciones!$A$2:$I$39,6,FALSE()) -> P1 | H8: =+VLOOKUP(B8,transacciones!$A$1:$I$39,7,FALSE()) -> Producción | I8: 07.1 | J8: Otras actividades agrícolas | K8: A | L8: =+VLOOKUP(K8,'Correl CIIU'!$A$1:$F$26,2,FALSE()) -> Agricultura, ganadería, silvicultura y pesca | M8: =+VLOOKUP(K8,'Correl CIIU'!$A$1:$F$26,3,FALSE()) -> Agricultura | N8: =+VLOOKUP(K8,'Correl CIIU'!$A$1:$F$26,4,FALSE()) -> Agriculture, forestry and fishing | O8: 1 | P8: =+VLOOKUP(O8,bio!$A$2:$B$4,2,FALSE()) -> Bioeconomía
A9: PANoc008 | B9: P11 | C9: =+VLOOKUP(B9,transacciones!$A$1:$I$39,2,FALSE()) -> ATC01 | D9: =+VLOOKUP($B9,transacciones!$A$1:$I$39,4,FALSE()) -> Producción de mercado | E9: =+VLOOKUP($B9,transacciones!$A$1:$I$39,4,FALSE()) -> Producción de mercado | F9: =+VLOOKUP(B9,transacciones!$A$2:$I$39,5,FALSE()) -> 1 | G9: =+VLOOKUP(B9,transacciones!$A$2:$I$39,6,FALSE()) -> P1 | H9: =+VLOOKUP(B9,transacciones!$A$1:$I$39,7,FALSE()) -> Producción | I9: 08.1 | J9: Cría de ganado bovino (excluye búfalo) | K9: A | L9: =+VLOOKUP(K9,'Correl CIIU'!$A$1:$F$26,2,FALSE()) -> Agricultura, ganadería, silvicultura y pesca | M9: =+VLOOKUP(K9,'Correl CIIU'!$A$1:$F$26,3,FALSE()) -> Agricultura | N9: =+VLOOKUP(K9,'Correl CIIU'!$A$1:$F$26,4,FALSE()) -> Agriculture, forestry and fishing | O9: 1 | P9: =+VLOOKUP(O9,bio!$A$2:$B$4,2,FALSE()) -> Bioeconomía
A10: PANoc009 | B10: P11 | C10: =+VLOOKUP(B10,transacciones!$A$1:$I$39,2,FALSE()) -> ATC01 | D10: =+VLOOKUP($B10,transacciones!$A$1:$I$39,4,FALSE()) -> Producción de mercado | E10: =+VLOOKUP($B10,transacciones!$A$1:$I$39,4,FALSE()) -> Producción de mercado | F10: =+VLOOKUP(B10,transacciones!$A$2:$I$39,5,FALSE()) -> 1 | G10: =+VLOOKUP(B10,transacciones!$A$2:$I$39,6,FALSE()) -> P1 | H10: =+VLOOKUP(B10,transacciones!$A$1:$I$39,7,FALSE()) -> Producción | I10: 08.2 | J10: Cría de ganado porcino | K10: A | L10: =+VLOOKUP(K10,'Correl CIIU'!$A$1:$F$26,2,FALSE()) -> Agricultura, ganadería, silvicultura y pesca | M10: =+VLOOKUP(K10,'Correl CIIU'!$A$1:$F$26,3,FALSE()) -> Agricultura | N10: =+VLOOKUP(K10,'Correl CIIU'!$A$1:$F$26,4,FALSE()) -> Agriculture, forestry and fishing | O10: 1 | P10: =+VLOOKUP(O10,bio!$A$2:$B$4,2,FALSE()) -> Bioeconomía
A11: PANoc010 | B11: P11 | C11: =+VLOOKUP(B11,transacciones!$A$1:$I$39,2,FALSE()) -> ATC01 | D11: =+VLOOKUP($B11,transacciones!$A$1:$I$39,4,FALSE()) -> Producción de mercado | E11: =+VLOOKUP($B11,transacciones!$A$1:$I$39,4,FALSE()) -> Producción de mercado | F11: =+VLOOKUP(B11,transacciones!$A$2:$I$39,5,FALSE()) -> 1 | G11: =+VLOOKUP(B11,transacciones!$A$2:$I$39,6,FALSE()) -> P1 | H11: =+VLOOKUP(B11,transacciones!$A$1:$I$39,7,FALSE()) -> Producción | I11: 08.3 | J11: Cría de aves de corral | K11: A | L11: =+VLOOKUP(K11,'Correl CIIU'!$A$1:$F$26,2,FALSE()) -> Agricultura, ganadería, silvicultura y pesca | M11: =+VLOOKUP(K11,'Correl CIIU'!$A$1:$F$26,3,FALSE()) -> Agricultura | N11: =+VLOOKUP(K11,'Correl CIIU'!$A$1:$F$26,4,FALSE()) -> Agriculture, forestry and fishing | O11: 1 | P11: =+VLOOKUP(O11,bio!$A$2:$B$4,2,FALSE()) -> Bioeconomía
A12: PANoc011 | B12: P11 | C12: =+VLOOKUP(B12,transacciones!$A$1:$I$39,2,FALSE()) -> ATC01 | D12: =+VLOOKUP($B12,transacciones!$A$1:$I$39,4,FALSE()) -> Producción de mercado | E12: =+VLOOKUP($B12,transacciones!$A$1:$I$39,4,FALSE()) -> Producción de mercado | F12: =+VLOOKUP(B12,transacciones!$A$2:$I$39,5,FALSE()) -> 1 | G12: =+VLOOKUP(B12,transacciones!$A$2:$I$39,6,FALSE()) -> P1 | H12: =+VLOOKUP(B12,transacciones!$A$1:$I$39,7,FALSE()) -> Producción | I12: 08.4 | J12: Cría de otros animales y obtención de subproductos | K12: A | L12: =+VLOOKUP(K12,'Correl CIIU'!$A$1:$F$26,2,FALSE()) -> Agricultura, ganadería, silvicultura y pesca | M12: =+VLOOKUP(K12,'Correl CIIU'!$A$1:$F$26,3,FALSE()) -> Agricultura | N12: =+VLOOKUP(K12,'Correl CIIU'!$A$1:$F$26,4,FALSE()) -> Agriculture, forestry and fishing | O12: 1 | P12: =+VLOOKUP(O12,bio!$A$2:$B$4,2,FALSE()) -> Bioeconomía
A13: PANoc012 | B13: P11 | C13: =+VLOOKUP(B13,transacciones!$A$1:$I$39,2,FALSE()) -> ATC01 | D13: =+VLOOKUP($B13,transacciones!$A$1:$I$39,4,FALSE()) -> Producción de mercado | E13: =+VLOOKUP($B13,transacciones!$A$1:$I$39,4,FALSE()) -> Producción de mercado | F13: =+VLOOKUP(B13,transacciones!$A$2:$I$39,5,FALSE()) -> 1 | G13: =+VLOOKUP(B13,transacciones!$A$2:$I$39,6,FALSE()) -> P1 | H13: =+VLOOKUP(B13,transacciones!$A$1:$I$39,7,FALSE()) -> Producción | I13: 09.1 | J13: Actividades de apoyo agropecuario | K13: A | L13: =+VLOOKUP(K13,'Correl CIIU'!$A$1:$F$26,2,FALSE()) -> Agricultura, ganadería, silvicultura y pesca | M13: =+VLOOKUP(K13,'Correl CIIU'!$A$1:$F$26,3,FALSE()) -> Agricultura | N13: =+VLOOKUP(K13,'Correl CIIU'!$A$1:$F$26,4,FALSE()) -> Agriculture, forestry and fishing | O13: 1 | P13: =+VLOOKUP(O13,bio!$A$2:$B$4,2,FALSE()) -> Bioeconomía
A14: PANoc013 | B14: P11 | C14: =+VLOOKUP(B14,transacciones!$A$1:$I$39,2,FALSE()) -> ATC01 | D14: =+VLOOKUP($B14,transacciones!$A$1:$I$39,4,FALSE()) -> Producción de mercado | E14: =+VLOOKUP($B14,transacciones!$A$1:$I$39,4,FALSE()) -> Producción de mercado | F14: =+VLOOKUP(B14,transacciones!$A$2:$I$39,5,FALSE()) -> 1 | G14: =+VLOOKUP(B14,transacciones!$A$2:$I$39,6,FALSE()) -> P1 | H14: =+VLOOKUP(B14,transacciones!$A$1:$I$39,7,FALSE()) -> Producción | I14: 10.1 | J14: Silvicultura, extracción de madera y actividades conexas | K14: A | L14: =+VLOOKUP(K14,'Correl CIIU'!$A$1:$F$26,2,FALSE()) -> Agricultura, ganadería, silvicultura y pesca | M14: =+VLOOKUP(K14,'Correl CIIU'!$A$1:$F$26,3,FALSE()) -> Agricultura | N14: =+VLOOKUP(K14,'Correl CIIU'!$A$1:$F$26,4,FALSE()) -> Agriculture, forestry and fishing | O14: 1 | P14: =+VLOOKUP(O14,bio!$A$2:$B$4,2,FALSE()) -> Bioeconomía
A15: PANoc014 | B15: P11 | C15: =+VLOOKUP(B15,transacciones!$A$1:$I$39,2,FALSE()) -> ATC01 | D15: =+VLOOKUP(B15,transacciones!$A$1:$I$39,3,FALSE()) -> Producción / Consumo intermedio | E15: =+VLOOKUP($B15,transacciones!$A$1:$I$39,4,FALSE()) -> Producción de mercado | F15: =+VLOOKUP(B15,transacciones!$A$2:$I$39,5,FALSE()) -> 1 | G15: =+VLOOKUP(B15,transacciones!$A$2:$I$39,6,FALSE()) -> P1 | H15: =+VLOOKUP(B15,transacciones!$A$1:$I$39,7,FALSE()) -> Producción | I15: 11.1 | J15: Pesca | K15: A | L15: =+VLOOKUP(K15,'Correl CIIU'!$A$1:$F$26,2,FALSE()) -> Agricultura, ganadería, silvicultura y pesca | M15: =+VLOOKUP(K15,'Correl CIIU'!$A$1:$F$26,3,FALSE()) -> Agricultura | N15: =+VLOOKUP(K15,'Correl CIIU'!$A$1:$F$26,4,FALSE()) -> Agriculture, forestry and fishing | O15: 1 | P15: =+VLOOKUP(O15,bio!$A$2:$B$4,2,FALSE()) -> Bioeconomía
A16: PANoc015 | B16: P11 | C16: =+VLOOKUP(B16,transacciones!$A$1:$I$39,2,FALSE()) -> ATC01 | D16: =+VLOOKUP(B16,transacciones!$A$1:$I$39,3,FALSE()) -> Producción / Consumo intermedio | E16: =+VLOOKUP($B16,transacciones!$A$1:$I$39,4,FALSE()) -> Producción de mercado | F16: =+VLOOKUP(B16,transacciones!$A$2:$I$39,5,FALSE()) -> 1 | G16: =+VLOOKUP(B16,transacciones!$A$2:$I$39,6,FALSE()) -> P1 | H16: =+VLOOKUP(B16,transacciones!$A$1:$I$39,7,FALSE()) -> Producción | I16: 12.1 | J16: Acuicultura | K16: A | L16: =+VLOOKUP(K16,'Correl CIIU'!$A$1:$F$26,2,FALSE()) -> Agricultura, ganadería, silvicultura y pesca | M16: =+VLOOKUP(K16,'Correl CIIU'!$A$1:$F$26,3,FALSE()) -> Agricultura | N16: =+VLOOKUP(K16,'Correl CIIU'!$A$1:$F$26,4,FALSE()) -> Agriculture, forestry and fishing | O16: 1 | P16: =+VLOOKUP(O16,bio!$A$2:$B$4,2,FALSE()) -> Bioeconomía
A17: PANoc016 | B17: P11 | C17: =+VLOOKUP(B17,transacciones!$A$1:$I$39,2,FALSE()) -> ATC01 | D17: =+VLOOKUP(B17,transacciones!$A$1:$I$39,3,FALSE()) -> Producción / Consumo intermedio | E17: =+VLOOKUP($B17,transacciones!$A$1:$I$39,4,FALSE()) -> Producción de mercado | F17: =+VLOOKUP(B17,transacciones!$A$2:$I$39,5,FALSE()) -> 1 | G17: =+VLOOKUP(B17,transacciones!$A$2:$I$39,6,FALSE()) -> P1 | H17: =+VLOOKUP(B17,transacciones!$A$1:$I$39,7,FALSE()) -> Producción | I17: 13.1 | J17: Explotación minas y canteras | K17: B | L17: =+VLOOKUP(K17,'Correl CIIU'!$A$1:$F$26,2,FALSE()) -> Explotación de minas y canteras | M17: =+VLOOKUP(K17,'Correl CIIU'!$A$1:$F$26,3,FALSE()) -> Minería | N17: =+VLOOKUP(K17,'Correl CIIU'!$A$1:$F$26,4,FALSE()) -> Mining and quarrying | O17: 3 | P17: =+VLOOKUP(O17,bio!$A$2:$B$4,2,FALSE()) -> No bioeconomía
A18: PANoc017 | B18: P11 | C18: =+VLOOKUP(B18,transacciones!$A$1:$I$39,2,FALSE()) -> ATC01 | D18: =+VLOOKUP($B18,transacciones!$A$1:$I$39,4,FALSE()) -> Producción de mercado | E18: =+VLOOKUP($B18,transacciones!$A$1:$I$39,4,FALSE()) -> Producción de mercado | F18: =+VLOOKUP(B18,transacciones!$A$2:$I$39,5,FALSE()) -> 1 | G18: =+VLOOKUP(B18,transacciones!$A$2:$I$39,6,FALSE()) -> P1 | H18: =+VLOOKUP(B18,transacciones!$A$1:$I$39,7,FALSE()) -> Producción | I18: 14.1 | J18: Procesamiento y conservación de carne | K18: C | L18: =+VLOOKUP(K18,'Correl CIIU'!$A$1:$F$26,2,FALSE()) -> Industrias manufactureras | M18: =+VLOOKUP(K18,'Correl CIIU'!$A$1:$F$26,3,FALSE()) -> Manufacturas | N18: =+VLOOKUP(K18,'Correl CIIU'!$A$1:$F$26,4,FALSE()) -> Manufacturing | O18: 1 | P18: =+VLOOKUP(O18,bio!$A$2:$B$4,2,FALSE()) -> Bioeconomía
A19: PANoc018 | B19: P11 | C19: =+VLOOKUP(B19,transacciones!$A$1:$I$39,2,FALSE()) -> ATC01 | D19: =+VLOOKUP($B19,transacciones!$A$1:$I$39,4,FALSE()) -> Producción de mercado | E19: =+VLOOKUP($B19,transacciones!$A$1:$I$39,4,FALSE()) -> Producción de mercado | F19: =+VLOOKUP(B19,transacciones!$A$2:$I$39,5,FALSE()) -> 1 | G19: =+VLOOKUP(B19,transacciones!$A$2:$I$39,6,FALSE()) -> P1 | H19: =+VLOOKUP(B19,transacciones!$A$1:$I$39,7,FALSE()) -> Producción | I19: 15.1 | J19: Procesamiento y conservación de pescado, crustáceos y moluscos | K19: C | L19: =+VLOOKUP(K19,'Correl CIIU'!$A$1:$F$26,2,FALSE()) -> Industrias manufactureras | M19: =+VLOOKUP(K19,'Correl CIIU'!$A$1:$F$26,3,FALSE()) -> Manufacturas | N19: =+VLOOKUP(K19,'Correl CIIU'!$A$1:$F$26,4,FALSE()) -> Manufacturing | O19: 1 | P19: =+VLOOKUP(O19,bio!$A$2:$B$4,2,FALSE()) -> Bioeconomía
A20: PANoc019 | B20: P11 | C20: =+VLOOKUP(B20,transacciones!$A$1:$I$39,2,FALSE()) -> ATC01 | D20: =+VLOOKUP($B20,transacciones!$A$1:$I$39,4,FALSE()) -> Producción de mercado | E20: =+VLOOKUP($B20,transacciones!$A$1:$I$39,4,FALSE()) -> Producción de mercado | F20: =+VLOOKUP(B20,transacciones!$A$2:$I$39,5,FALSE()) -> 1 | G20: =+VLOOKUP(B20,transacciones!$A$2:$I$39,6,FALSE()) -> P1 | H20: =+VLOOKUP(B20,transacciones!$A$1:$I$39,7,FALSE()) -> Producción | I20: 16.1 | J20: Procesamiento y conservación de frutas y vegetales | K20: C | L20: =+VLOOKUP(K20,'Correl CIIU'!$A$1:$F$26,2,FALSE()) -> Industrias manufactureras | M20: =+VLOOKUP(K20,'Correl CIIU'!$A$1:$F$26,3,FALSE()) -> Manufacturas | N20: =+VLOOKUP(K20,'Correl CIIU'!$A$1:$F$26,4,FALSE()) -> Manufacturing | O20: 1 | P20: =+VLOOKUP(O20,bio!$A$2:$B$4,2,FALSE()) -> Bioeconomía
A21: PANoc020 | B21: P11 | C21: =+VLOOKUP(B21,transacciones!$A$1:$I$39,2,FALSE()) -> ATC01 | D21: =+VLOOKUP($B21,transacciones!$A$1:$I$39,4,FALSE()) -> Producción de mercado | E21: =+VLOOKUP($B21,transacciones!$A$1:$I$39,4,FALSE()) -> Producción de mercado | F21: =+VLOOKUP(B21,transacciones!$A$2:$I$39,5,FALSE()) -> 1 | G21: =+VLOOKUP(B21,transacciones!$A$2:$I$39,6,FALSE()) -> P1 | H21: =+VLOOKUP(B21,transacciones!$A$1:$I$39,7,FALSE()) -> Producción | I21: 17.1 | J21: Elaboración de aceites y grasas de origen vegetal y animal | K21: C | L21: =+VLOOKUP(K21,'Correl CIIU'!$A$1:$F$26,2,FALSE()) -> Industrias manufactureras | M21: =+VLOOKUP(K21,'Correl CIIU'!$A$1:$F$26,3,FALSE()) -> Manufacturas | N21: =+VLOOKUP(K21,'Correl CIIU'!$A$1:$F$26,4,FALSE()) -> Manufacturing | O21: 1 | P21: =+VLOOKUP(O21,bio!$A$2:$B$4,2,FALSE()) -> Bioeconomía
A22: PANoc021 | B22: P11 | C22: =+VLOOKUP(B22,transacciones!$A$1:$I$39,2,FALSE()) -> ATC01 | D22: =+VLOOKUP($B22,transacciones!$A$1:$I$39,4,FALSE()) -> Producción de mercado | E22: =+VLOOKUP($B22,transacciones!$A$1:$I$39,4,FALSE()) -> Producción de mercado | F22: =+VLOOKUP(B22,transacciones!$A$2:$I$39,5,FALSE()) -> 1 | G22: =+VLOOKUP(B22,transacciones!$A$2:$I$39,6,FALSE()) -> P1 | H22: =+VLOOKUP(B22,transacciones!$A$1:$I$39,7,FALSE()) -> Producción | I22: 18.1 | J22: Elaboración de productos lácteos | K22: C | L22: =+VLOOKUP(K22,'Correl CIIU'!$A$1:$F$26,2,FALSE()) -> Industrias manufactureras | M22: =+VLOOKUP(K22,'Correl CIIU'!$A$1:$F$26,3,FALSE()) -> Manufacturas | N22: =+VLOOKUP(K22,'Correl CIIU'!$A$1:$F$26,4,FALSE()) -> Manufacturing | O22: 1 | P22: =+VLOOKUP(O22,bio!$A$2:$B$4,2,FALSE()) -> Bioeconomía
A23: PANoc022 | B23: P11 | C23: =+VLOOKUP(B23,transacciones!$A$1:$I$39,2,FALSE()) -> ATC01 | D23: =+VLOOKUP($B23,transacciones!$A$1:$I$39,4,FALSE()) -> Producción de mercado | E23: =+VLOOKUP($B23,transacciones!$A$1:$I$39,4,FALSE()) -> Producción de mercado | F23: =+VLOOKUP(B23,transacciones!$A$2:$I$39,5,FALSE()) -> 1 | G23: =+VLOOKUP(B23,transacciones!$A$2:$I$39,6,FALSE()) -> P1 | H23: =+VLOOKUP(B23,transacciones!$A$1:$I$39,7,FALSE()) -> Producción | I23: 19.1 | J23: Elaboración de productos de molinería, almidones y productos derivados del almidón | K23: C | L23: =+VLOOKUP(K23,'Correl CIIU'!$A$1:$F$26,2,FALSE()) -> Industrias manufactureras | M23: =+VLOOKUP(K23,'Correl CIIU'!$A$1:$F$26,3,FALSE()) -> Manufacturas | N23: =+VLOOKUP(K23,'Correl CIIU'!$A$1:$F$26,4,FALSE()) -> Manufacturing | O23: 1 | P23: =+VLOOKUP(O23,bio!$A$2:$B$4,2,FALSE()) -> Bioeconomía
A24: PANoc023 | B24: P11 | C24: =+VLOOKUP(B24,transacciones!$A$1:$I$39,2,FALSE()) -> ATC01 | D24: =+VLOOKUP($B24,transacciones!$A$1:$I$39,4,FALSE()) -> Producción de mercado | E24: =+VLOOKUP($B24,transacciones!$A$1:$I$39,4,FALSE()) -> Producción de mercado | F24: =+VLOOKUP(B24,transacciones!$A$2:$I$39,5,FALSE()) -> 1 | G24: =+VLOOKUP(B24,transacciones!$A$2:$I$39,6,FALSE()) -> P1 | H24: =+VLOOKUP(B24,transacciones!$A$1:$I$39,7,FALSE()) -> Producción | I24: 19.2 | J24: Elaboración de otros productos alimenticios | K24: C | L24: =+VLOOKUP(K24,'Correl CIIU'!$A$1:$F$26,2,FALSE()) -> Industrias manufactureras | M24: =+VLOOKUP(K24,'Correl CIIU'!$A$1:$F$26,3,FALSE()) -> Manufacturas | N24: =+VLOOKUP(K24,'Correl CIIU'!$A$1:$F$26,4,FALSE()) -> Manufacturing | O24: 1 | P24: =+VLOOKUP(O24,bio!$A$2:$B$4,2,FALSE()) -> Bioeconomía
A25: PANoc024 | B25: P11 | C25: =+VLOOKUP(B25,transacciones!$A$1:$I$39,2,FALSE()) -> ATC01 | D25: =+VLOOKUP($B25,transacciones!$A$1:$I$39,4,FALSE()) -> Producción de mercado | E25: =+VLOOKUP($B25,transacciones!$A$1:$I$39,4,FALSE()) -> Producción de mercado | F25: =+VLOOKUP(B25,transacciones!$A$2:$I$39,5,FALSE()) -> 1 | G25: =+VLOOKUP(B25,transacciones!$A$2:$I$39,6,FALSE()) -> P1 | H25: =+VLOOKUP(B25,transacciones!$A$1:$I$39,7,FALSE()) -> Producción | I25: 20.1 | J25: Elaboración de bebidas y tabaco | K25: C | L25: =+VLOOKUP(K25,'Correl CIIU'!$A$1:$F$26,2,FALSE()) -> Industrias manufactureras | M25: =+VLOOKUP(K25,'Correl CIIU'!$A$1:$F$26,3,FALSE()) -> Manufacturas | N25: =+VLOOKUP(K25,'Correl CIIU'!$A$1:$F$26,4,FALSE()) -> Manufacturing | O25: 1 | P25: =+VLOOKUP(O25,bio!$A$2:$B$4,2,FALSE()) -> Bioeconomía
A26: PANoc025 | B26: P11 | C26: =+VLOOKUP(B26,transacciones!$A$1:$I$39,2,FALSE()) -> ATC01 | D26: =+VLOOKUP($B26,transacciones!$A$1:$I$39,4,FALSE()) -> Producción de mercado | E26: =+VLOOKUP($B26,transacciones!$A$1:$I$39,4,FALSE()) -> Producción de mercado | F26: =+VLOOKUP(B26,transacciones!$A$2:$I$39,5,FALSE()) -> 1 | G26: =+VLOOKUP(B26,transacciones!$A$2:$I$39,6,FALSE()) -> P1 | H26: =+VLOOKUP(B26,transacciones!$A$1:$I$39,7,FALSE()) -> Producción | I26: 21.1 | J26: Fabricación de productos textiles y prendas de vestir | K26: C | L26: =+VLOOKUP(K26,'Correl CIIU'!$A$1:$F$26,2,FALSE()) -> Industrias manufactureras | M26: =+VLOOKUP(K26,'Correl CIIU'!$A$1:$F$26,3,FALSE()) -> Manufacturas | N26: =+VLOOKUP(K26,'Correl CIIU'!$A$1:$F$26,4,FALSE()) -> Manufacturing | O26: 2 | P26: =+VLOOKUP(O26,bio!$A$2:$B$4,2,FALSE()) -> Bioeconomía extendida
A27: PANoc026 | B27: P11 | C27: =+VLOOKUP(B27,transacciones!$A$1:$I$39,2,FALSE()) -> ATC01 | D27: =+VLOOKUP(B27,transacciones!$A$1:$I$39,3,FALSE()) -> Producción / Consumo intermedio | E27: =+VLOOKUP($B27,transacciones!$A$1:$I$39,4,FALSE()) -> Producción de mercado | F27: =+VLOOKUP(B27,transacciones!$A$2:$I$39,5,FALSE()) -> 1 | G27: =+VLOOKUP(B27,transacciones!$A$2:$I$39,6,FALSE()) -> P1 | H27: =+VLOOKUP(B27,transacciones!$A$1:$I$39,7,FALSE()) -> Producción | I27: 22.1 | J27: Fabricación de cuero, productos conexos y calzado | K27: C | L27: =+VLOOKUP(K27,'Correl CIIU'!$A$1:$F$26,2,FALSE()) -> Industrias manufactureras | M27: =+VLOOKUP(K27,'Correl CIIU'!$A$1:$F$26,3,FALSE()) -> Manufacturas | N27: =+VLOOKUP(K27,'Correl CIIU'!$A$1:$F$26,4,FALSE()) -> Manufacturing | O27: 2 | P27: =+VLOOKUP(O27,bio!$A$2:$B$4,2,FALSE()) -> Bioeconomía extendida
A28: PANoc027 | B28: P11 | C28: =+VLOOKUP(B28,transacciones!$A$1:$I$39,2,FALSE()) -> ATC01 | D28: =+VLOOKUP(B28,transacciones!$A$1:$I$39,3,FALSE()) -> Producción / Consumo intermedio | E28: =+VLOOKUP($B28,transacciones!$A$1:$I$39,4,FALSE()) -> Producción de mercado | F28: =+VLOOKUP(B28,transacciones!$A$2:$I$39,5,FALSE()) -> 1 | G28: =+VLOOKUP(B28,transacciones!$A$2:$I$39,6,FALSE()) -> P1 | H28: =+VLOOKUP(B28,transacciones!$A$1:$I$39,7,FALSE()) -> Producción | I28: 23.1 | J28: Producción de madera y fabricación de productos de madera y corcho, excepto muebles; fabricación de artículos de paja y de materiales trenzables | K28: C | L28: =+VLOOKUP(K28,'Correl CIIU'!$A$1:$F$26,2,FALSE()) -> Industrias manufactureras | M28: =+VLOOKUP(K28,'Correl CIIU'!$A$1:$F$26,3,FALSE()) -> Manufacturas | N28: =+VLOOKUP(K28,'Correl CIIU'!$A$1:$F$26,4,FALSE()) -> Manufacturing | O28: 1 | P28: =+VLOOKUP(O28,bio!$A$2:$B$4,2,FALSE()) -> Bioeconomía
A29: PANoc028 | B29: P11 | C29: =+VLOOKUP(B29,transacciones!$A$1:$I$39,2,FALSE()) -> ATC01 | D29: =+VLOOKUP(B29,transacciones!$A$1:$I$39,3,FALSE()) -> Producción / Consumo intermedio | E29: =+VLOOKUP($B29,transacciones!$A$1:$I$39,4,FALSE()) -> Producción de mercado | F29: =+VLOOKUP(B29,transacciones!$A$2:$I$39,5,FALSE()) -> 1 | G29: =+VLOOKUP(B29,transacciones!$A$2:$I$39,6,FALSE()) -> P1 | H29: =+VLOOKUP(B29,transacciones!$A$1:$I$39,7,FALSE()) -> Producción | I29: 24.1 | J29: Fabricacion de papel y productos de papel | K29: C | L29: =+VLOOKUP(K29,'Correl CIIU'!$A$1:$F$26,2,FALSE()) -> Industrias manufactureras | M29: =+VLOOKUP(K29,'Correl CIIU'!$A$1:$F$26,3,FALSE()) -> Manufacturas | N29: =+VLOOKUP(K29,'Correl CIIU'!$A$1:$F$26,4,FALSE()) -> Manufacturing | O29: 1 | P29: =+VLOOKUP(O29,bio!$A$2:$B$4,2,FALSE()) -> Bioeconomía
A30: PANoc029 | B30: P11 | C30: =+VLOOKUP(B30,transacciones!$A$1:$I$39,2,FALSE()) -> ATC01 | D30: =+VLOOKUP($B30,transacciones!$A$1:$I$39,4,FALSE()) -> Producción de mercado | E30: =+VLOOKUP($B30,transacciones!$A$1:$I$39,4,FALSE()) -> Producción de mercado | F30: =+VLOOKUP(B30,transacciones!$A$2:$I$39,5,FALSE()) -> 1 | G30: =+VLOOKUP(B30,transacciones!$A$2:$I$39,6,FALSE()) -> P1 | H30: =+VLOOKUP(B30,transacciones!$A$1:$I$39,7,FALSE()) -> Producción | I30: 25.1 | J30: Actividades de impresión y servicios conexos | K30: C | L30: =+VLOOKUP(K30,'Correl CIIU'!$A$1:$F$26,2,FALSE()) -> Industrias manufactureras | M30: =+VLOOKUP(K30,'Correl CIIU'!$A$1:$F$26,3,FALSE()) -> Manufacturas | N30: =+VLOOKUP(K30,'Correl CIIU'!$A$1:$F$26,4,FALSE()) -> Manufacturing | O30: 2 | P30: =+VLOOKUP(O30,bio!$A$2:$B$4,2,FALSE()) -> Bioeconomía extendida
A31: PANoc030 | B31: P11 | C31: =+VLOOKUP(B31,transacciones!$A$1:$I$39,2,FALSE()) -> ATC01 | D31: =+VLOOKUP($B31,transacciones!$A$1:$I$39,4,FALSE()) -> Producción de mercado | E31: =+VLOOKUP($B31,transacciones!$A$1:$I$39,4,FALSE()) -> Producción de mercado | F31: =+VLOOKUP(B31,transacciones!$A$2:$I$39,5,FALSE()) -> 1 | G31: =+VLOOKUP(B31,transacciones!$A$2:$I$39,6,FALSE()) -> P1 | H31: =+VLOOKUP(B31,transacciones!$A$1:$I$39,7,FALSE()) -> Producción | I31: 26.1 | J31: Fabricación de sustancias y productos químicos | K31: C | L31: =+VLOOKUP(K31,'Correl CIIU'!$A$1:$F$26,2,FALSE()) -> Industrias manufactureras | M31: =+VLOOKUP(K31,'Correl CIIU'!$A$1:$F$26,3,FALSE()) -> Manufacturas | N31: =+VLOOKUP(K31,'Correl CIIU'!$A$1:$F$26,4,FALSE()) -> Manufacturing | O31: 2 | P31: =+VLOOKUP(O31,bio!$A$2:$B$4,2,FALSE()) -> Bioeconomía extendida
A32: PANoc031 | B32: P11 | C32: =+VLOOKUP(B32,transacciones!$A$1:$I$39,2,FALSE()) -> ATC01 | D32: =+VLOOKUP($B32,transacciones!$A$1:$I$39,4,FALSE()) -> Producción de mercado | E32: =+VLOOKUP($B32,transacciones!$A$1:$I$39,4,FALSE()) -> Producción de mercado | F32: =+VLOOKUP(B32,transacciones!$A$2:$I$39,5,FALSE()) -> 1 | G32: =+VLOOKUP(B32,transacciones!$A$2:$I$39,6,FALSE()) -> P1 | H32: =+VLOOKUP(B32,transacciones!$A$1:$I$39,7,FALSE()) -> Producción | I32: 27.1 | J32: Fabricación de productos farmacéuticos, sustancias químicas medicinales y de productos botánicos | K32: C | L32: =+VLOOKUP(K32,'Correl CIIU'!$A$1:$F$26,2,FALSE()) -> Industrias manufactureras | M32: =+VLOOKUP(K32,'Correl CIIU'!$A$1:$F$26,3,FALSE()) -> Manufacturas | N32: =+VLOOKUP(K32,'Correl CIIU'!$A$1:$F$26,4,FALSE()) -> Manufacturing | O32: 2 | P32: =+VLOOKUP(O32,bio!$A$2:$B$4,2,FALSE()) -> Bioeconomía extendida
A33: PANoc032 | B33: P11 | C33: =+VLOOKUP(B33,transacciones!$A$1:$I$39,2,FALSE()) -> ATC01 | D33: =+VLOOKUP($B33,transacciones!$A$1:$I$39,4,FALSE()) -> Producción de mercado | E33: =+VLOOKUP($B33,transacciones!$A$1:$I$39,4,FALSE()) -> Producción de mercado | F33: =+VLOOKUP(B33,transacciones!$A$2:$I$39,5,FALSE()) -> 1 | G33: =+VLOOKUP(B33,transacciones!$A$2:$I$39,6,FALSE()) -> P1 | H33: =+VLOOKUP(B33,transacciones!$A$1:$I$39,7,FALSE()) -> Producción | I33: 28.1 | J33: Fabricación de productos de caucho y plástico | K33: C | L33: =+VLOOKUP(K33,'Correl CIIU'!$A$1:$F$26,2,FALSE()) -> Industrias manufactureras | M33: =+VLOOKUP(K33,'Correl CIIU'!$A$1:$F$26,3,FALSE()) -> Manufacturas | N33: =+VLOOKUP(K33,'Correl CIIU'!$A$1:$F$26,4,FALSE()) -> Manufacturing | O33: 3 | P33: =+VLOOKUP(O33,bio!$A$2:$B$4,2,FALSE()) -> No bioeconomía
A34: PANoc033 | B34: P11 | C34: =+VLOOKUP(B34,transacciones!$A$1:$I$39,2,FALSE()) -> ATC01 | D34: =+VLOOKUP($B34,transacciones!$A$1:$I$39,4,FALSE()) -> Producción de mercado | E34: =+VLOOKUP($B34,transacciones!$A$1:$I$39,4,FALSE()) -> Producción de mercado | F34: =+VLOOKUP(B34,transacciones!$A$2:$I$39,5,FALSE()) -> 1 | G34: =+VLOOKUP(B34,transacciones!$A$2:$I$39,6,FALSE()) -> P1 | H34: =+VLOOKUP(B34,transacciones!$A$1:$I$39,7,FALSE()) -> Producción | I34: 29.1 | J34: Fabricación de cemento, cal y yeso | K34: C | L34: =+VLOOKUP(K34,'Correl CIIU'!$A$1:$F$26,2,FALSE()) -> Industrias manufactureras | M34: =+VLOOKUP(K34,'Correl CIIU'!$A$1:$F$26,3,FALSE()) -> Manufacturas | N34: =+VLOOKUP(K34,'Correl CIIU'!$A$1:$F$26,4,FALSE()) -> Manufacturing | O34: 3 | P34: =+VLOOKUP(O34,bio!$A$2:$B$4,2,FALSE()) -> No bioeconomía
A35: PANoc034 | B35: P11 | C35: =+VLOOKUP(B35,transacciones!$A$1:$I$39,2,FALSE()) -> ATC01 | D35: =+VLOOKUP($B35,transacciones!$A$1:$I$39,4,FALSE()) -> Producción de mercado | E35: =+VLOOKUP($B35,transacciones!$A$1:$I$39,4,FALSE()) -> Producción de mercado | F35: =+VLOOKUP(B35,transacciones!$A$2:$I$39,5,FALSE()) -> 1 | G35: =+VLOOKUP(B35,transacciones!$A$2:$I$39,6,FALSE()) -> P1 | H35: =+VLOOKUP(B35,transacciones!$A$1:$I$39,7,FALSE()) -> Producción | I35: 30.1 | J35: Fabricación de otros productos minerales no metálicos | K35: C | L35: =+VLOOKUP(K35,'Correl CIIU'!$A$1:$F$26,2,FALSE()) -> Industrias manufactureras | M35: =+VLOOKUP(K35,'Correl CIIU'!$A$1:$F$26,3,FALSE()) -> Manufacturas | N35: =+VLOOKUP(K35,'Correl CIIU'!$A$1:$F$26,4,FALSE()) -> Manufacturing | O35: 3 | P35: =+VLOOKUP(O35,bio!$A$2:$B$4,2,FALSE()) -> No bioeconomía
A36: PANoc035 | B36: P11 | C36: =+VLOOKUP(B36,transacciones!$A$1:$I$39,2,FALSE()) -> ATC01 | D36: =+VLOOKUP($B36,transacciones!$A$1:$I$39,4,FALSE()) -> Producción de mercado | E36: =+VLOOKUP($B36,transacciones!$A$1:$I$39,4,FALSE()) -> Producción de mercado | F36: =+VLOOKUP(B36,transacciones!$A$2:$I$39,5,FALSE()) -> 1 | G36: =+VLOOKUP(B36,transacciones!$A$2:$I$39,6,FALSE()) -> P1 | H36: =+VLOOKUP(B36,transacciones!$A$1:$I$39,7,FALSE()) -> Producción | I36: 31.1 | J36: Fabricación de metales comunes | K36: C | L36: =+VLOOKUP(K36,'Correl CIIU'!$A$1:$F$26,2,FALSE()) -> Industrias manufactureras | M36: =+VLOOKUP(K36,'Correl CIIU'!$A$1:$F$26,3,FALSE()) -> Manufacturas | N36: =+VLOOKUP(K36,'Correl CIIU'!$A$1:$F$26,4,FALSE()) -> Manufacturing | O36: 3 | P36: =+VLOOKUP(O36,bio!$A$2:$B$4,2,FALSE()) -> No bioeconomía
A37: PANoc036 | B37: P11 | C37: =+VLOOKUP(B37,transacciones!$A$1:$I$39,2,FALSE()) -> ATC01 | D37: =+VLOOKUP($B37,transacciones!$A$1:$I$39,4,FALSE()) -> Producción de mercado | E37: =+VLOOKUP($B37,transacciones!$A$1:$I$39,4,FALSE()) -> Producción de mercado | F37: =+VLOOKUP(B37,transacciones!$A$2:$I$39,5,FALSE()) -> 1 | G37: =+VLOOKUP(B37,transacciones!$A$2:$I$39,6,FALSE()) -> P1 | H37: =+VLOOKUP(B37,transacciones!$A$1:$I$39,7,FALSE()) -> Producción | I37: 31.2 | J37: Fabricación de productos metalicos elaborados, excepto maquinaria y equipo | K37: C | L37: =+VLOOKUP(K37,'Correl CIIU'!$A$1:$F$26,2,FALSE()) -> Industrias manufactureras | M37: =+VLOOKUP(K37,'Correl CIIU'!$A$1:$F$26,3,FALSE()) -> Manufacturas | N37: =+VLOOKUP(K37,'Correl CIIU'!$A$1:$F$26,4,FALSE()) -> Manufacturing | O37: 3 | P37: =+VLOOKUP(O37,bio!$A$2:$B$4,2,FALSE()) -> No bioeconomía
A38: PANoc037 | B38: P11 | C38: =+VLOOKUP(B38,transacciones!$A$1:$I$39,2,FALSE()) -> ATC01 | D38: =+VLOOKUP($B38,transacciones!$A$1:$I$39,4,FALSE()) -> Producción de mercado | E38: =+VLOOKUP($B38,transacciones!$A$1:$I$39,4,FALSE()) -> Producción de mercado | F38: =+VLOOKUP(B38,transacciones!$A$2:$I$39,5,FALSE()) -> 1 | G38: =+VLOOKUP(B38,transacciones!$A$2:$I$39,6,FALSE()) -> P1 | H38: =+VLOOKUP(B38,transacciones!$A$1:$I$39,7,FALSE()) -> Producción | I38: 32.1 | J38: Otras industrias manufactureras | K38: C | L38: =+VLOOKUP(K38,'Correl CIIU'!$A$1:$F$26,2,FALSE()) -> Industrias manufactureras | M38: =+VLOOKUP(K38,'Correl CIIU'!$A$1:$F$26,3,FALSE()) -> Manufacturas | N38: =+VLOOKUP(K38,'Correl CIIU'!$A$1:$F$26,4,FALSE()) -> Manufacturing | O38: 3 | P38: =+VLOOKUP(O38,bio!$A$2:$B$4,2,FALSE()) -> No bioeconomía
A39: PANoc038 | B39: P11 | C39: =+VLOOKUP(B39,transacciones!$A$1:$I$39,2,FALSE()) -> ATC01 | D39: =+VLOOKUP(B39,transacciones!$A$1:$I$39,3,FALSE()) -> Producción / Consumo intermedio | E39: =+VLOOKUP($B39,transacciones!$A$1:$I$39,4,FALSE()) -> Producción de mercado | F39: =+VLOOKUP(B39,transacciones!$A$2:$I$39,5,FALSE()) -> 1 | G39: =+VLOOKUP(B39,transacciones!$A$2:$I$39,6,FALSE()) -> P1 | H39: =+VLOOKUP(B39,transacciones!$A$1:$I$39,7,FALSE()) -> Producción | I39: 33.1 | J39: Reparación, mantenimiento e instalación de maquinaria y equipo comercial e industrial | K39: C | L39: =+VLOOKUP(K39,'Correl CIIU'!$A$1:$F$26,2,FALSE()) -> Industrias manufactureras | M39: =+VLOOKUP(K39,'Correl CIIU'!$A$1:$F$26,3,FALSE()) -> Manufacturas | N39: =+VLOOKUP(K39,'Correl CIIU'!$A$1:$F$26,4,FALSE()) -> Manufacturing | O39: 3 | P39: =+VLOOKUP(O39,bio!$A$2:$B$4,2,FALSE()) -> No bioeconomía
A40: PANoc039 | B40: P11 | C40: =+VLOOKUP(B40,transacciones!$A$1:$I$39,2,FALSE()) -> ATC01 | D40: =+VLOOKUP(B40,transacciones!$A$1:$I$39,3,FALSE()) -> Producción / Consumo intermedio | E40: =+VLOOKUP($B40,transacciones!$A$1:$I$39,4,FALSE()) -> Producción de mercado | F40: =+VLOOKUP(B40,transacciones!$A$2:$I$39,5,FALSE()) -> 1 | G40: =+VLOOKUP(B40,transacciones!$A$2:$I$39,6,FALSE()) -> P1 | H40: =+VLOOKUP(B40,transacciones!$A$1:$I$39,7,FALSE()) -> Producción | I40: 34.1 | J40: Suministro de electricidad, gas, vapor y aire acondicionado | K40: D | L40: =+VLOOKUP(K40,'Correl CIIU'!$A$1:$F$26,2,FALSE()) -> Suministro de electricidad, gas, vapor y aire acondicionado | M40: =+VLOOKUP(K40,'Correl CIIU'!$A$1:$F$26,3,FALSE()) -> Servicios básicos | N40: =+VLOOKUP(K40,'Correl CIIU'!$A$1:$F$26,4,FALSE()) -> Electricity, gas, steam and air conditioning supply | O40: 3 | P40: =+VLOOKUP(O40,bio!$A$2:$B$4,2,FALSE()) -> No bioeconomía
...

Sheet Correl CIIU
A1: CIIU Secciones | B1: CIIU Secciones descripción | C1: CIIU Corto | D1: CIIU English
A2: A | B2: Agricultura, ganadería, silvicultura y pesca | C2: Agricultura | D2: Agriculture, forestry and fishing
A3: B | B3: Explotación de minas y canteras | C3: Minería | D3: Mining and quarrying
A4: C | B4: Industrias manufactureras | C4: Manufacturas | D4: Manufacturing
A5: C | B5: Industrias manufactureras | C5: Manufacturas | D5: Manufacturing
A6: C | B6: Industrias manufactureras | C6: Manufacturas | D6: Manufacturing
A7: D | B7: Suministro de electricidad, gas, vapor y aire acondicionado | C7: Servicios básicos | D7: Electricity, gas, steam and air conditioning supply
A8: E | B8: Suministro de agua; evacuación de aguas residuales, gestión de desechos y descontaminación | C8: Suministro de agua | D8: Water supply; sewerage, waste management and remediation activities
A9: F | B9: Construcción | C9: Construcción | D9: Construction
A10: G | B10: Comercio al por mayor y al por menor; reparación de vehículos automotores y motocicletas | C10: Comercio | D10: Wholesale and retail trade; repair of motor vehicles and motorcycles
A11: H | B11: Transporte y almacenamiento | C11: Transporte y almacenamiento | D11: Transportation and storage
A12: J | B12: Información y comunicaciones | C12: Información y comunicaciones | D12: Information and communication
... A26: - | B26: - | C26: - | D26: -

Sheet at_columnas
A1: Código Transacciones | B1: Área transaccional columnas No. | C1: Área transaccional | D1: Transacciones | E1: Correlativo Transacciones Agregadas | F1: Código Transacciones Agregadas | G1: Transacciones Agregadas | H1: corr_ntg2 | I1: id_area_columnas
A2: P10 | B2: ATC01 | C2: Producción / Consumo intermedio | D2: Producción | E2: 1 | F2: P1 | G2: Producción | H2: 1 | I2: 0
A3: P11 | B3: ATC01 | C3: Producción / Consumo intermedio | D3: Producción de mercado | E3: 1 | F3: P1 | G3: Producción | H3: 2 | I3: 1
A4: P12 | B4: ATC01 | C4: Producción / Consumo intermedio | D4: Producción para uso final propio | E4: 1 | F4: P1 | G4: Producción | H4: 3 | I4: 2
A5: P13 | B5: ATC01 | C5: Producción / Consumo intermedio | D5: Otra producción no de mercado | E5: 1 | F5: P1 | G5: Producción | H5: 4 | I5: 3
A6: P20 | B6: ATC01 | C6: Producción / Consumo intermedio | D6: Consumo | E6: 2 | F6: P2 | G6: Consumo intermedio | H6: 5 | I6: 0
A7: P21 | B7: ATC01 | C7: Producción / Consumo intermedio | D7: Consumo intermedio de mercado | E7: 2 | F7: P2 | G7: Consumo intermedio | H7: 6 | I7: 1
A8: P22 | B8: ATC01 | C8: Producción / Consumo intermedio | D8: Consumo intermedio para uso final propio | E8: 2 | F8: P2 | G8: Consumo intermedio | H8: 7 | I8: 2
A9: P23 | B9: ATC01 | C9: Producción / Consumo intermedio | D9: Consumo intermedio no de mercado | E9: 2 | F9: P2 | G9: Consumo intermedio | H9: 8 | I9: 3
A10: Pa31 | B10: ATC06 | C10: Gasto de consumo final | D10: Gasto de consumo final de los hogares | E10: 3 | F10: P3 | G10: Gasto de consumo final | H10: 9 | I10: 9
A11: Pb30 | B11: ATC06 | C11: Consumo final | D11: Gasto de consumo ISFLH | E11: 3 | F11: P3 | G11: Gasto de consumo final | H11: 10 | I11: 9
A12: Pb31 | B12: ATC06 | C12: Consumo final | D12: Gasto de consumo individual ISFLSH | E12: 3 | F12: P3 | G12: Gasto de consumo final | H12: 11 | I12: 9
A13: Pb32 | B13: ATC06 | C13: Consumo final | D13: Gasto de consumo colectivo ISFLSH | E13: 3 | F13: P3 | G13: Gasto de consumo final | H13: 12 | I13: 9
A14: Pc30 | B14: ATC06 | C14: Consumo final | D14: Gasto de consumo de gobierno | E14: 3 | F14: P3 | G14: Gasto de consumo final
A15: Pc31 | B15: ATC06 | C15: Consumo final | D15: Gasto de consumo individual de gobierno | E15: 3 | F15: P3 | G15: Gasto de consumo final | H15: 13 | I15: 9
A16: Pc32 | B16: ATC06 | C16: Consumo final | D16: Gasto de consumo colectivo de gobierno | E16: 3 | F16: P3 | G16: Gasto de consumo final | H16: 14 | I16: 9
A17: P41 | B17: ATC06 | C17: Consumo final | D17: Consumo individual efectivo | E17: 4 | F17: P4 | G17: Consumo final efectivo | H17: 15 | I17: 9
A18: P42 | B18: ATC06 | C18: Consumo final | D18: Consumo colectivo efectivo | E18: 4 | F18: P4 | G18: Consumo final efectivo | H18: 16 | I18: 9
A19: P51b | B19: ATC07 | C19: Consumo final | D19: Formación bruta de capital fijo | E19: 5 | F19: P5 | G19: Formación de capital | H19: 17 | I19: 10
A20: P51c | B20: ATC07 | C20: Consumo final | D20: Consumo de capital fijo | E20: 5 | F20: P5 | G20: Formación de capital | H20: 18 | I20: 10
A21: P52 | B21: ATC07 | C21: Consumo final | D21: Variación de existencias | E21: 5 | F21: P5 | G21: Formación de capital | H21: 19 | I21: 10
A22: P53 | B22: ATC07 | C22: Consumo final | D22: Adquisiciones menos disposiciones de objetos valiosos | E22: 5 | F22: P5 | G22: Formación de capital | H22: 20 | I22: 10
A23: P60 | B23: ATC02 | C23: Exportaciones / Importaciones | D23: Exportaciones de bienes y servicios | E23: 6 | F23: P6 | G23: Exportaciones de bienes y servicios | H23: 21 | I23: 4
A24: P61 | B24: ATC02 | C24: Exportaciones / Importaciones | D24: Exportaciones de bienes | E24: 6 | F24: P6 | G24: Exportaciones de bienes y servicios | H24: 22 | I24: 4
A25: P62 | B25: ATC02 | C25: Exportaciones / Importaciones | D25: Exportaciones de servicios | E25: 6 | F25: P6 | G25: Exportaciones de bienes y servicios | H25: 23 | I25: 4
A26: P70 | B26: ATC02 | C26: Exportaciones / Importaciones | D26: Importaciones de bienes y servicios | E26: 7 | F26: P7 | G26: Importaciones de bienes y servicios | H26: 24
A27: P71 | B27: ATC02 | C27: Exportaciones / Importaciones | D27: Importaciones de bienes | E27: 7 | F27: P7 | G27: Importaciones de bienes y servicios | H27: 25 | I27: 4
A28: P72 | B28: ATC02 | C28: Exportaciones / Importaciones | D28: Importaciones de servicios | E28: 7 | F28: P7 | G28: Importaciones de bienes y servicios | H28: 26 | I28: 4
A29: CIF | B29: ATC03 | C29: Ajuste CIF/FOB | D29: Ajuste CIF/FOB sobre importaciones | E29: 8 | F29: CIF | G29: Ajuste CIF/FOB sobre importaciones | H29: 27 | I29: 5
A30: D211 | B30: ATC04 | C30: Impuestos menos subvenciones sobre los productos | D30: Impuestos tipo valor agregado (IVA) | E30: 9 | F30: D2 | G30: Impuestos sobre la producción y las importaciones | H30: 28 | I30: 6
A31: D212 | B31: ATC04 | C31: Impuestos menos subvenciones sobre los productos | D31: Impuestos y derechos sobre las importaciones excepto IVA | E31: 9 | F31: D2 | G31: Impuestos sobre la producción y las importaciones | H31: 29 | I31: 6
A32: D213 | B32: ATC04 | C32: Impuestos menos subvenciones sobre los productos | D32: Impuestos sobre las exportaciones | E32: 9 | F32: D2 | G32: Impuestos sobre la producción y las importaciones | H32: 30 | I32: 6
A33: D214 | B33: ATC04 | C33: Impuestos menos subvenciones sobre los productos | D33: Impuestos sobre los productos, excepto IVA e impuestos sobre las importaciones | E33: 9 | F33: D2 | G33: Impuestos sobre la producción y las importaciones | H33: 31 | I33: 6
A34: D291 | B34: ATC04 | C34: Impuestos menos subvenciones sobre los productos | D34: Otros impuestos sobre la producción | E34: 10 | F34: D29 | G34: Otros impuestos sobre la producción | H34: 32 | I34: 6
A35: D31 | B35: ATC04 | C35: Impuestos menos subvenciones sobre los productos | D35: Subvenciones a los productos | E35: 11 | F35: D3 | G35: Subvenciones | H35: 33 | I35: 7
A36: D39 | B36: ATCO4 | C36: Impuestos menos subvenciones sobre los productos | D36: Otras subvenciones a la producción | E36: 11 | F36: D3 | G36: Subvenciones | H36: 34 | I36: 7
A37: M11 | B37: ATC05 | C37: Márgenes de distribución | D37: Márgenes de comercio | E37: 12 | F37: M1 | G37: Márgenes de distribución | H37: 35 | I37: 8
A38: M12 | B38: ATC05 | C38: Márgenes de distribución | D38: Márgenes de transporte | E38: 12 | F38: M1 | G38: Márgenes de distribución | H38: 36 | I38: 8
A39: M13 | B39: ATC05 | C39: Márgenes de distribución | D39: Márgenes de distribución de electricidad | E39: 12 | F39: M1 | G39: Márgenes de distribución | H39: 37 | I39: 8

Sheet transacciones
A1: Código Transacciones | B1: Área transaccional columnas No. | C1: Área transaccional | D1: Transacciones | E1: Correlativo Transacciones Agregadas | F1: Código Transacciones Agregadas | G1: Transacciones Agregadas | H1: corr_ntg2 | I1: id_area_columnas
A2: P10 | B2: ATC01 | C2: Producción / Consumo intermedio | D2: Producción | E2: 1 | F2: P1 | G2: Producción | H2: 1 | I2: 0
A3: P11 | B3: ATC01 | C3: Producción / Consumo intermedio | D3: Producción de mercado | E3: 1 | F3: P1 | G3: Producción | H3: 2 | I3: 1
A4: P12 | B4: ATC01 | C4: Producción / Consumo intermedio | D4: Producción para uso final propio | E4: 1 | F4: P1 | G4: Producción | H4: 3 | I4: 2
A5: P13 | B5: ATC01 | C5: Producción / Consumo intermedio | D5: Otra producción no de mercado | E5: 1 | F5: P1 | G5: Producción | H5: 4 | I5: 3
A6: P20 | B6: ATC01 | C6: Producción / Consumo intermedio | D6: Consumo | E6: 2 | F6: P2 | G6: Consumo intermedio | H6: 5 | I6: 0
A7: P21 | B7: ATC01 | C7: Producción / Consumo intermedio | D7: Consumo intermedio de mercado | E7: 2 | F7: P2 | G7: Consumo intermedio | H7: 6 | I7: 1
A8: P22 | B8: ATC01 | C8: Producción / Consumo intermedio | D8: Consumo intermedio para uso final propio | E8: 2 | F8: P2 | G8: Consumo intermedio | H8: 7 | I8: 2
A9: P23 | B9: ATC01 | C9: Producción / Consumo intermedio | D9: Consumo intermedio no de mercado | E9: 2 | F9: P2 | G9: Consumo intermedio | H9: 8 | I9: 3
A10: Pa31 | B10: ATC06 | C10: Gasto de consumo final | D10: Gasto de consumo final de los hogares | E10: 3 | F10: P3 | G10: Gasto de consumo final | H10: 9 | I10: 9
A11: Pb30 | B11: ATC06 | C11: Consumo final | D11: Gasto de consumo ISFLH | E11: 3 | F11: P3 | G11: Gasto de consumo final | H11: 10 | I11: 9
A12: Pb31 | B12: ATC06 | C12: Consumo final | D12: Gasto de consumo individual ISFLSH | E12: 3 | F12: P3 | G12: Gasto de consumo final | H12: 11 | I12: 9
A13: Pb32 | B13: ATC06 | C13: Consumo final | D13: Gasto de consumo colectivo ISFLSH | E13: 3 | F13: P3 | G13: Gasto de consumo final | H13: 12 | I13: 9
A14: Pc30 | B14: ATC06 | C14: Consumo final | D14: Gasto de consumo de gobierno | E14: 3 | F14: P3 | G14: Gasto de consumo final
A15: Pc31 | B15: ATC06 | C15: Consumo final | D15: Gasto de consumo individual de gobierno | E15: 3 | F15: P3 | G15: Gasto de consumo final | H15: 13 | I15: 9
A16: Pc32 | B16: ATC06 | C16: Consumo final | D16: Gasto de consumo colectivo de gobierno | E16: 3 | F16: P3 | G16: Gasto de consumo final | H16: 14 | I16: 9
A17: P41 | B17: ATC06 | C17: Consumo final | D17: Consumo individual efectivo | E17: 4 | F17: P4 | G17: Consumo final efectivo | H17: 15 | I17: 9
A18: P42 | B18: ATC06 | C18: Consumo final | D18: Consumo colectivo efectivo | E18: 4 | F18: P4 | G18: Consumo final efectivo | H18: 16 | I18: 9
A19: P51b | B19: ATC07 | C19: Consumo final | D19: Formación bruta de capital fijo | E19: 5 | F19: P5 | G19: Formación de capital | H19: 17 | I19: 10
A20: P51c | B20: ATC07 | C20: Consumo final | D20: Consumo de capital fijo | E20: 5 | F20: P5 | G20: Formación de capital | H20: 18 | I20: 10
A21: P52 | B21: ATC07 | C21: Consumo final | D21: Variación de existencias | E21: 5 | F21: P5 | G21: Formación de capital | H21: 19 | I21: 10
A22: P53 | B22: ATC07 | C22: Consumo final | D22: Adquisiciones menos disposiciones de objetos valiosos | E22: 5 | F22: P5 | G22: Formación de capital | H22: 20 | I22: 10
A23: P60 | B23: ATC02 | C23: Exportaciones / Importaciones | D23: Exportaciones de bienes y servicios | E23: 6 | F23: P6 | G23: Exportaciones de bienes y servicios | H23: 21 | I23: 4
A24: P61 | B24: ATC02 | C24: Exportaciones / Importaciones | D24: Exportaciones de bienes | E24: 6 | F24: P6 | G24: Exportaciones de bienes y servicios | H24: 22 | I24: 4
A25: P62 | B25: ATC02 | C25: Exportaciones / Importaciones | D25: Exportaciones de servicios | E25: 6 | F25: P6 | G25: Exportaciones de bienes y servicios | H25: 23 | I25: 4
A26: P70 | B26: ATC02 | C26: Exportaciones / Importaciones | D26: Importaciones de bienes y servicios | E26: 7 | F26: P7 | G26: Importaciones de bienes y servicios | H26: 24
A27: P71 | B27: ATC02 | C27: Exportaciones / Importaciones | D27: Importaciones de bienes | E27: 7 | F27: P7 | G27: Importaciones de bienes y servicios | H27: 25 | I27: 4
A28: P72 | B28: ATC02 | C28: Exportaciones / Importaciones | D28: Importaciones de servicios | E28: 7 | F28: P7 | G28: Importaciones de bienes y servicios | H28: 26 | I28: 4
A29: CIF | B29: ATC03 | C29: Ajuste CIF/FOB | D29: Ajuste CIF/FOB sobre importaciones | E29: 8 | F29: CIF | G29: Ajuste CIF/FOB sobre importaciones | H29: 27 | I29: 5
A30: D211 | B30: ATC04 | C30: Impuestos menos subvenciones sobre los productos | D30: Impuestos tipo valor agregado (IVA) | E30: 9 | F30: D2 | G30: Impuestos sobre la producción y las importaciones | H30: 28 | I30: 6
A31: D212 | B31: ATC04 | C31: Impuestos menos subvenciones sobre los productos | D31: Impuestos y derechos sobre las importaciones excepto IVA | E31: 9 | F31: D2 | G31: Impuestos sobre la producción y las importaciones | H31: 29 | I31: 6
A32: D213 | B32: ATC04 | C32: Impuestos menos subvenciones sobre los productos | D32: Impuestos sobre las exportaciones | E32: 9 | F32: D2 | G32: Impuestos sobre la producción y las importaciones | H32: 30 | I32: 6
A33: D214 | B33: ATC04 | C33: Impuestos menos subvenciones sobre los productos | D33: Impuestos sobre los productos, excepto IVA e impuestos sobre las importaciones | E33: 9 | F33: D2 | G33: Impuestos sobre la producción y las importaciones | H33: 31 | I33: 6
A34: D291 | B34: ATC04 | C34: Impuestos menos subvenciones sobre los productos | D34: Otros impuestos sobre la producción | E34: 10 | F34: D29 | G34: Otros impuestos sobre la producción | H34: 32 | I34: 6
A35: D31 | B35: ATC04 | C35: Impuestos menos subvenciones sobre los productos | D35: Subvenciones a los productos | E35: 11 | F35: D3 | G35: Subvenciones | H35: 33 | I35: 7
A36: D39 | B36: ATCO4 | C36: Impuestos menos subvenciones sobre los productos | D36: Otras subvenciones a la producción | E36: 11 | F36: D3 | G36: Subvenciones | H36: 34 | I36: 7
A37: M11 | B37: ATC05 | C37: Márgenes de distribución | D37: Márgenes de comercio | E37: 12 | F37: M1 | G37: Márgenes de distribución | H37: 35 | I37: 8
A38: M12 | B38: ATC05 | C38: Márgenes de distribución | D38: Márgenes de transporte | E38: 12 | F38: M1 | G38: Márgenes de distribución | H38: 36 | I38: 8
A39: M13 | B39: ATC05 | C39: Márgenes de distribución | D39: Márgenes de distribución de electricidad | E39: 12 | F39: M1 | G39: Márgenes de distribución | H39: 37 | I39: 8

Sheet AT_FILAS
A1: Áreas Transaccionales Filas No. | B1: Áreas Transaccionales Filas Descripción | C1: Codigo Transacción Filas
A2: ATF01 | B2: Producción | C2: 1
A3: ATF02 | B3: Consumo intermedio | C3: 2
A4: ATF03 | B4: Ajuste CIF/FOB | C4: 3
A5: ATF04 | B5: Compras directas en el exterior por residentes | C5: 4
A6: ATF05 | B6: Compras directas en el territorio nacional por no residentes | C6: 5
A7: ATF06 | B7: Valor Agregado | C7: 6
A8: ATF07 | B8: Puestos de trabajo | C8: 7

Sheet filas
A1: Filas | B1: Áreas Transaccionales Filas No. | C1: Áreas Transaccionales Filas Descripción | D1: Codigo Transacción Filas | E1: Código Nomenclatura Local de Productos | F1: Nomenclatura Local de Productos | G1: Clasificación Productos | H1: Cod_Bioec Productos | I1: Tipo de bioeconomía Productos | J1: Sectores produuctos | K1: Cód_Div_CPC_3 | L1: División CPC_3 | M1: Cód_Div_CPC_2 | N1: División CPC_2 | O1: Cod. Elem. Def. Bioeconomía | P1: Tipo de elemento | Q1: Código CPC | R1: Elemento CPC | S1: Código Bioeconomía | T1: Clasificación Bioeconomí
A2: PANof001 | B2: ATF01 | C2: =VLOOKUP(B2, AT_FILAS!$A$2:$C$8,2,FALSE()) -> Producción | D2: =VLOOKUP(B2, AT_FILAS!$A$2:$C$8,3,FALSE()) -> 1 | E2: 0101 | F2: TRIGO | G2: Productos agricolas_Cereales | H2: 1 | I2: Bioeconomía de productos básicos | J2: Productos agropecuarios | K2: 1 | L2: =VLOOKUP(K2,clasif_filas!$A$2:$J$39,2,FALSE()) -> Productos de la agricultura, la horticultura y la jardinería comercial | M2: =VLOOKUP(K2,clasif_filas!$A$2:$J$39,3,FALSE()) -> 1 | N2: =VLOOKUP(K2,clasif_filas!$A$2:$J$39,4,FALSE()) -> Productos de la agricultura, la horticultura y la jardinería comercial | O2: =VLOOKUP(K2,clasif_filas!$A$2:$J$39,5,FALSE()) -> 1 | P2: =VLOOKUP(K2,clasif_filas!$A$2:$J$39,6,FALSE()) -> Biomasa que se cultiva para producir alimentos, forrajes, fibras y energía | Q2: =VLOOKUP(K2,clasif_filas!$A$2:$J$39,7,FALSE()) -> 0 | R2: =VLOOKUP(K2,clasif_filas!$A$2:$J$39,8,FALSE()) -> Productos de la agricultura, la silvicultura yla pesca | S2: =VLOOKUP(K2,clasif_filas!$A$2:$J$39,9,FALSE()) -> 1 | T2: =VLOOKUP(K2,clasif_filas!$A$2:$J$39,10,FALSE()) -> Bioeconomía
A3: PANof002 | B3: ATF01 | C3: =VLOOKUP(B3, AT_FILAS!$A$2:$C$8,2,FALSE()) -> Producción | D3: =VLOOKUP(B3, AT_FILAS!$A$2:$C$8,3,FALSE()) -> 1 | E3: 0102 | F3: OTROS CEREALES (EXCL. MAÍZ Y ARROZ) | G3: Productos agricolas_Cereales | H3: 1 | I3: Bioeconomía de productos básicos | J3: Productos agropecuarios | K3: 1 | L3: =VLOOKUP(K3,clasif_filas!$A$2:$J$39,2,FALSE()) -> Productos de la agricultura, la horticultura y la jardinería comercial | M3: =VLOOKUP(K3,clasif_filas!$A$2:$J$39,3,FALSE()) -> 1 | N3: =VLOOKUP(K3,clasif_filas!$A$2:$J$39,4,FALSE()) -> Productos de la agricultura, la horticultura y la jardinería comercial | O3: =VLOOKUP(K3,clasif_filas!$A$2:$J$39,5,FALSE()) -> 1 | P3: =VLOOKUP(K3,clasif_filas!$A$2:$J$39,6,FALSE()) -> Biomasa que se cultiva para producir alimentos, forrajes, fibras y energía | Q3: =VLOOKUP(K3,clasif_filas!$A$2:$J$39,7,FALSE()) -> 0 | R3: =VLOOKUP(K3,clasif_filas!$A$2:$J$39,8,FALSE()) -> Productos de la agricultura, la silvicultura yla pesca | S3: =VLOOKUP(K3,clasif_filas!$A$2:$J$39,9,FALSE()) -> 1 | T3: =VLOOKUP(K3,clasif_filas!$A$2:$J$39,10,FALSE()) -> Bioeconomía
A4: PANof003 | B4: ATF01 | C4: =VLOOKUP(B4, AT_FILAS!$A$2:$C$8,2,FALSE()) -> Producción | D4: =VLOOKUP(B4, AT_FILAS!$A$2:$C$8,3,FALSE()) -> 1 | E4: 0103 | F4: LEGUMBRES | G4: Productos agropecuarios_Vegetales | H4: 1 | I4: Bioeconomía de productos básicos | J4: Productos agropecuarios | K4: 1 | L4: =VLOOKUP(K4,clasif_filas!$A$2:$J$39,2,FALSE()) -> Productos de la agricultura, la horticultura y la jardinería comercial | M4: =VLOOKUP(K4,clasif_filas!$A$2:$J$39,3,FALSE()) -> 1 | N4: =VLOOKUP(K4,clasif_filas!$A$2:$J$39,4,FALSE()) -> Productos de la agricultura, la horticultura y la jardinería comercial | O4: =VLOOKUP(K4,clasif_filas!$A$2:$J$39,5,FALSE()) -> 1 | P4: =VLOOKUP(K4,clasif_filas!$A$2:$J$39,6,FALSE()) -> Biomasa que se cultiva para producir alimentos, forrajes, fibras y energía | Q4: =VLOOKUP(K4,clasif_filas!$A$2:$J$39,7,FALSE()) -> 0 | R4: =VLOOKUP(K4,clasif_filas!$A$2:$J$39,8,FALSE()) -> Productos de la agricultura, la silvicultura yla pesca | S4: =VLOOKUP(K4,clasif_filas!$A$2:$J$39,9,FALSE()) -> 1 | T4: =VLOOKUP(K4,clasif_filas!$A$2:$J$39,10,FALSE()) -> Bioeconomía
A5: PANof004 | B5: ATF01 | C5: =VLOOKUP(B5, AT_FILAS!$A$2:$C$8,2,FALSE()) -> Producción | D5: =VLOOKUP(B5, AT_FILAS!$A$2:$C$8,3,FALSE()) -> 1 | E5: 0104 | F5: SEMILLAS OLEAGINOSAS | G5: Productos agricolas_Oleaginosas | H5: 1 | I5: Bioeconomía de productos básicos | J5: Productos agropecuarios | K5: 1 | L5: =VLOOKUP(K5,clasif_filas!$A$2:$J$39,2,FALSE()) -> Productos de la agricultura, la horticultura y la jardinería comercial | M5: =VLOOKUP(K5,clasif_filas!$A$2:$J$39,3,FALSE()) -> 1 | N5: =VLOOKUP(K5,clasif_filas!$A$2:$J$39,4,FALSE()) -> Productos de la agricultura, la horticultura y la jardinería comercial | O5: =VLOOKUP(K5,clasif_filas!$A$2:$J$39,5,FALSE()) -> 1 | P5: =VLOOKUP(K5,clasif_filas!$A$2:$J$39,6,FALSE()) -> Biomasa que se cultiva para producir alimentos, forrajes, fibras y energía | Q5: =VLOOKUP(K5,clasif_filas!$A$2:$J$39,7,FALSE()) -> 0 | R5: =VLOOKUP(K5,clasif_filas!$A$2:$J$39,8,FALSE()) -> Productos de la agricultura, la silvicultura yla pesca | S5: =VLOOKUP(K5,clasif_filas!$A$2:$J$39,9,FALSE()) -> 1 | T5: =VLOOKUP(K5,clasif_filas!$A$2:$J$39,10,FALSE()) -> Bioeconomía
A6: PANof005 | B6: ATF01 | C6: =VLOOKUP(B6, AT_FILAS!$A$2:$C$8,2,FALSE()) -> Producción | D6: =VLOOKUP(B6, AT_FILAS!$A$2:$C$8,3,FALSE()) -> 1 | E6: 0201 | F6: MAÍZ | G6: Productos agricolas_Cereales | H6: 1 | I6: Bioeconomía de productos básicos | J6: Productos agropecuarios | K6: 1 | L6: =VLOOKUP(K6,clasif_filas!$A$2:$J$39,2,FALSE()) -> Productos de la agricultura, la horticultura y la jardinería comercial | M6: =VLOOKUP(K6,clasif_filas!$A$2:$J$39,3,FALSE()) -> 1 | N6: =VLOOKUP(K6,clasif_filas!$A$2:$J$39,4,FALSE()) -> Productos de la agricultura, la horticultura y la jardinería comercial | O6: =VLOOKUP(K6,clasif_filas!$A$2:$J$39,5,FALSE()) -> 1 | P6: =VLOOKUP(K6,clasif_filas!$A$2:$J$39,6,FALSE()) -> Biomasa que se cultiva para producir alimentos, forrajes, fibras y energía | Q6: =VLOOKUP(K6,clasif_filas!$A$2:$J$39,7,FALSE()) -> 0 | R6: =VLOOKUP(K6,clasif_filas!$A$2:$J$39,8,FALSE()) -> Productos de la agricultura, la silvicultura yla pesca | S6: =VLOOKUP(K6,clasif_filas!$A$2:$J$39,9,FALSE()) -> 1 | T6: =VLOOKUP(K6,clasif_filas!$A$2:$J$39,10,FALSE()) -> Bioeconomía
A7: PANof006 | B7: ATF01 | C7: =VLOOKUP(B7, AT_FILAS!$A$2:$C$8,2,FALSE()) -> Producción | D7: =VLOOKUP(B7, AT_FILAS!$A$2:$C$8,3,FALSE()) -> 1 | E7: 0301 | F7: ARROZ | G7: Productos agricolas_Cereales | H7: 1 | I7: Bioeconomía de productos básicos | J7: Productos agropecuarios | K7: 1 | L7: =VLOOKUP(K7,clasif_filas!$A$2:$J$39,2,FALSE()) -> Productos de la agricultura, la horticultura y la jardinería comercial | M7: =VLOOKUP(K7,clasif_filas!$A$2:$J$39,3,FALSE()) -> 1 | N7: =VLOOKUP(K7,clasif_filas!$A$2:$J$39,4,FALSE()) -> Productos de la agricultura, la horticultura y la jardinería comercial | O7: =VLOOKUP(K7,clasif_filas!$A$2:$J$39,5,FALSE()) -> 1 | P7: =VLOOKUP(K7,clasif_filas!$A$2:$J$39,6,FALSE()) -> Biomasa que se cultiva para producir alimentos, forrajes, fibras y energía | Q7: =VLOOKUP(K7,clasif_filas!$A$2:$J$39,7,FALSE()) -> 0 | R7: =VLOOKUP(K7,clasif_filas!$A$2:$J$39,8,FALSE()) -> Productos de la agricultura, la silvicultura yla pesca | S7: =VLOOKUP(K7,clasif_filas!$A$2:$J$39,9,FALSE()) -> 1 | T7: =VLOOKUP(K7,clasif_filas!$A$2:$J$39,10,FALSE()) -> Bioeconomía
