Workbook

Sheet rows
A1: row_id | B1: Filas
A2: bra_v01_q01_r0001 | B2: BRAof001
A3: bra_v01_q01_r0002 | B3: BRAof002
A4: bra_v01_q01_r0003 | B4: BRAof003
A5: bra_v01_q01_r0004 | B5: BRAof004
A6: bra_v01_q01_r0005 | B6: BRAof005
A7: bra_v01_q01_r0006 | B7: BRAof006
A8: bra_v01_q01_r0007 | B8: BRAof007
A9: bra_v01_q01_r0008 | B9: BRAof008
A10: bra_v01_q01_r0009 | B10: BRAof009
A11: bra_v01_q01_r0010 | B11: BRAof010
A12: bra_v01_q01_r0011 | B12: BRAof011
... A129: bra_v01_q01_r0128 | B129: BRAof128
A130: bra_v01_q01_r0129
A131: bra_v01_q01_r0130
A132: bra_v01_q02_r0001 | B132: BRAof001
A133: bra_v01_q02_r0002 | B133: BRAof002
A134: bra_v01_q02_r0003 | B134: BRAof003
A135: bra_v01_q02_r0004 | B135: BRAof004
A136: bra_v01_q02_r0005 | B136: BRAof005
A137: bra_v01_q02_r0006 | B137: BRAof006
A138: bra_v01_q02_r0007 | B138: BRAof007
A139: bra_v01_q02_r0008 | B139: BRAof008
A140: bra_v01_q02_r0009 | B140: BRAof009
A141: bra_v01_q02_r0010 | B141: BRAof010
A142: bra_v01_q02_r0011 | B142: BRAof011
A143: bra_v01_q02_r0012 | B143: BRAof012
... A259: bra_v01_q02_r0128 | B259: BRAof128
A260: bra_v01_q02_r0129
A261: bra_v01_q02_r0130
A262: bra_v01_q03_r0001 | B262: BRAof001
A263: bra_v01_q03_r0002 | B263: BRAof002
A264: bra_v01_q03_r0003 | B264: BRAof003
A265: bra_v01_q03_r0004 | B265: BRAof004
A266: bra_v01_q03_r0005 | B266: BRAof005
A267: bra_v01_q03_r0006 | B267: BRAof006
A268: bra_v01_q03_r0007 | B268: BRAof007
A269: bra_v01_q03_r0008 | B269: BRAof008
A270: bra_v01_q03_r0009 | B270: BRAof009
A271: bra_v01_q03_r0010 | B271: BRAof010
...

Sheet columns
A1: col_id | B1: Columnas
A2: bra_v01_q01_c0001 | B2: BRAoc001
A3: bra_v01_q01_c0002 | B3: BRAoc002
A4: bra_v01_q01_c0003 | B4: BRAoc003
A5: bra_v01_q01_c0004 | B5: BRAoc004
A6: bra_v01_q01_c0005 | B6: BRAoc005
A7: bra_v01_q01_c0006 | B7: BRAoc006
A8: bra_v01_q01_c0007 | B8: BRAoc007
A9: bra_v01_q01_c0008 | B9: BRAoc008
A10: bra_v01_q01_c0009 | B10: BRAoc009
A11: bra_v01_q01_c0010 | B11: BRAoc010
A12: bra_v01_q01_c0011 | B12: BRAoc011
... A71: bra_v01_q02_c0001 | B71: BRAoc070
A72: bra_v01_q03_c0001
A73: bra_v01_q03_c0002 | B73: BRAoc071
A74: bra_v01_q03_c0003 | B74: BRAoc072
A75: bra_v01_q03_c0004 | B75: BRAoc073
A76: bra_v01_q03_c0005 | B76: BRAoc074
A77: bra_v01_q03_c0006 | B77: BRAoc075
A78: bra_v01_q03_c0007 | B78: BRAoc076
A79: bra_v01_q03_c0008 | B79: BRAoc077
A80: bra_v01_q03_c0009
A81: bra_v01_q04_c0001 | B81: BRAuc001
A82: bra_v01_q04_c0002 | B82: BRAuc002
A83: bra_v01_q04_c0003 | B83: BRAuc003
A84: bra_v01_q04_c0004 | B84: BRAuc004
A85: bra_v01_q04_c0005 | B85: BRAuc005
A86: bra_v01_q04_c0006 | B86: BRAuc006
A87: bra_v01_q04_c0007 | B87: BRAuc007
A88: bra_v01_q04_c0008 | B88: BRAuc008
A89: bra_v01_q04_c0009 | B89: BRAuc009
A90: bra_v01_q04_c0010 | B90: BRAuc010
A91: bra_v01_q04_c0011 | B91: BRAuc011
A92: bra_v01_q04_c0012 | B92: BRAuc012
... A226: bra_v01_q06_c0069 | B226: BRAvc069

Sheet quadrants
A1: quadrant_code | B1: quadrant | C1: target_table | D1: cell_range | E1: excl_rows | F1: excl_cols
A2: q01 | B2: producao | C2: Supply | D2: C6:BS135 | E2: 129,130 | F2: 69
A3: q02 | B3: importacao | C3: Supply | D3: C6:C135 | E3: 129,130
A4: q03 | B4: oferta | C4: Supply | D4: C6:K135 | E4: 129,130 | F4: 1,8,9
A5: q04 | B5: CI | C5: Use | D5: C6:BS135 | E5: 129,130 | F5: 69
A6: q05 | B6: demanda | C6: Use | D6: C6:J135 | E6: 129,130 | F6: 7,8
A7: q06 | B7: VA | C7: Value Added | D7: B6:BR6 | F7: 69

Sheet columnas
A1: Columnas | B1: Código Transacciones | C1: Área transaccional columnas No. | D1: Área transaccional | E1: Transacciones | F1: Correlativo Transacciones Agregadas | G1: Código Transacciones Agregadas | H1: Transacciones Agregadas | I1: Código Clasificación Actividades | J1: Descripción Actividades | K1: CIIU Secciones | L1: CIIU Secciones descripción | M1: CIIU Corto | N1: CIIU English | O1: Correlativo Bioeconomía Actividades | P1: Bioeconomía Actividades
A2: BRAoc001 | B2: P10 | C2: =+VLOOKUP(B2,'transacciones '!$A$2:$I$39,2,FALSE()) -> ATC01 | D2: =+VLOOKUP(B2,'transacciones '!$A$2:$I$39,3,FALSE()) -> Producción / Consumo intermedio | E2: =+VLOOKUP(B2,'transacciones '!$A$2:$I$39,4,FALSE()) -> Producción | F2: =+VLOOKUP(B2,'transacciones '!$A$2:$I$39,5,FALSE()) -> 1 | G2: =+VLOOKUP(B2,'transacciones '!$A$2:$I$39,6,FALSE()) -> P1 | H2: =+VLOOKUP(B2,'transacciones '!$A$2:$I$39,7,FALSE()) -> Producción | I2: 0191 | J2: 0191 Agricultura, inclusive o apoio à agricultura e a pós-colheita | K2: A | L2: =+VLOOKUP(K2,'Correl CIIU'!$A$1:$F$26,2,FALSE()) -> Agricultura, ganadería, silvicultura y pesca | M2: =+VLOOKUP(K2,'Correl CIIU'!$A$1:$F$26,3,FALSE()) -> Agricultura | N2: =+VLOOKUP(K2,'Correl CIIU'!$A$1:$F$26,4,FALSE()) -> Agriculture, forestry and fishing | O2: 1 | P2: =+VLOOKUP(O2,bio!$A$2:$B$4,2,FALSE()) -> Bioeconomía
A3: BRAoc002 | B3: P10 | C3: =+VLOOKUP(B3,'transacciones '!$A$2:$I$39,2,FALSE()) -> ATC01 | D3: =+VLOOKUP(B3,'transacciones '!$A$2:$I$39,3,FALSE()) -> Producción / Consumo intermedio | E3: =+VLOOKUP(B3,'transacciones '!$A$2:$I$39,4,FALSE()) -> Producción | F3: =+VLOOKUP(B3,'transacciones '!$A$2:$I$39,5,FALSE()) -> 1 | G3: =+VLOOKUP(B3,'transacciones '!$A$2:$I$39,6,FALSE()) -> P1 | H3: =+VLOOKUP(B3,'transacciones '!$A$2:$I$39,7,FALSE()) -> Producción | I3: 0192 | J3: 0192 Pecuária, inclusive o apoio à pecuária | K3: A | L3: =+VLOOKUP(K3,'Correl CIIU'!$A$1:$F$26,2,FALSE()) -> Agricultura, ganadería, silvicultura y pesca | M3: =+VLOOKUP(K3,'Correl CIIU'!$A$1:$F$26,3,FALSE()) -> Agricultura | N3: =+VLOOKUP(K3,'Correl CIIU'!$A$1:$F$26,4,FALSE()) -> Agriculture, forestry and fishing | O3: 1 | P3: =+VLOOKUP(O3,bio!$A$2:$B$4,2,FALSE()) -> Bioeconomía
A4: BRAoc003 | B4: P10 | C4: =+VLOOKUP(B4,'transacciones '!$A$2:$I$39,2,FALSE()) -> ATC01 | D4: =+VLOOKUP(B4,'transacciones '!$A$2:$I$39,3,FALSE()) -> Producción / Consumo intermedio | E4: =+VLOOKUP(B4,'transacciones '!$A$2:$I$39,4,FALSE()) -> Producción | F4: =+VLOOKUP(B4,'transacciones '!$A$2:$I$39,5,FALSE()) -> 1 | G4: =+VLOOKUP(B4,'transacciones '!$A$2:$I$39,6,FALSE()) -> P1 | H4: =+VLOOKUP(B4,'transacciones '!$A$2:$I$39,7,FALSE()) -> Producción | I4: 0280 | J4: 0280 Produção florestal; pesca e aquicultura | K4: A | L4: =+VLOOKUP(K4,'Correl CIIU'!$A$1:$F$26,2,FALSE()) -> Agricultura, ganadería, silvicultura y pesca | M4: =+VLOOKUP(K4,'Correl CIIU'!$A$1:$F$26,3,FALSE()) -> Agricultura | N4: =+VLOOKUP(K4,'Correl CIIU'!$A$1:$F$26,4,FALSE()) -> Agriculture, forestry and fishing | O4: 1 | P4: =+VLOOKUP(O4,bio!$A$2:$B$4,2,FALSE()) -> Bioeconomía
A5: BRAoc004 | B5: P10 | C5: =+VLOOKUP(B5,'transacciones '!$A$2:$I$39,2,FALSE()) -> ATC01 | D5: =+VLOOKUP(B5,'transacciones '!$A$2:$I$39,3,FALSE()) -> Producción / Consumo intermedio | E5: =+VLOOKUP(B5,'transacciones '!$A$2:$I$39,4,FALSE()) -> Producción | F5: =+VLOOKUP(B5,'transacciones '!$A$2:$I$39,5,FALSE()) -> 1 | G5: =+VLOOKUP(B5,'transacciones '!$A$2:$I$39,6,FALSE()) -> P1 | H5: =+VLOOKUP(B5,'transacciones '!$A$2:$I$39,7,FALSE()) -> Producción | I5: 0580 | J5: 0580 Extração de carvão mineral e de minerais não-metálicos | K5: B | L5: =+VLOOKUP(K5,'Correl CIIU'!$A$1:$F$26,2,FALSE()) -> Explotación de minas y canteras | M5: =+VLOOKUP(K5,'Correl CIIU'!$A$1:$F$26,3,FALSE()) -> Minería | N5: =+VLOOKUP(K5,'Correl CIIU'!$A$1:$F$26,4,FALSE()) -> Mining and quarrying | O5: 3 | P5: =+VLOOKUP(O5,bio!$A$2:$B$4,2,FALSE()) -> No bioeconomía
A6: BRAoc005 | B6: P10 | C6: =+VLOOKUP(B6,'transacciones '!$A$2:$I$39,2,FALSE()) -> ATC01 | D6: =+VLOOKUP(B6,'transacciones '!$A$2:$I$39,3,FALSE()) -> Producción / Consumo intermedio | E6: =+VLOOKUP(B6,'transacciones '!$A$2:$I$39,4,FALSE()) -> Producción | F6: =+VLOOKUP(B6,'transacciones '!$A$2:$I$39,5,FALSE()) -> 1 | G6: =+VLOOKUP(B6,'transacciones '!$A$2:$I$39,6,FALSE()) -> P1 | H6: =+VLOOKUP(B6,'transacciones '!$A$2:$I$39,7,FALSE()) -> Producción | I6: 0680 | J6: 0680 Extração de petróleo e gás, inclusive as atividades de apoio | K6: B | L6: =+VLOOKUP(K6,'Correl CIIU'!$A$1:$F$26,2,FALSE()) -> Explotación de minas y canteras | M6: =+VLOOKUP(K6,'Correl CIIU'!$A$1:$F$26,3,FALSE()) -> Minería | N6: =+VLOOKUP(K6,'Correl CIIU'!$A$1:$F$26,4,FALSE()) -> Mining and quarrying | O6: 3 | P6: =+VLOOKUP(O6,bio!$A$2:$B$4,2,FALSE()) -> No bioeconomía
A7: BRAoc006 | B7: P10 | C7: =+VLOOKUP(B7,'transacciones '!$A$2:$I$39,2,FALSE()) -> ATC01 | D7: =+VLOOKUP(B7,'transacciones '!$A$2:$I$39,3,FALSE()) -> Producción / Consumo intermedio | E7: =+VLOOKUP(B7,'transacciones '!$A$2:$I$39,4,FALSE()) -> Producción | F7: =+VLOOKUP(B7,'transacciones '!$A$2:$I$39,5,FALSE()) -> 1 | G7: =+VLOOKUP(B7,'transacciones '!$A$2:$I$39,6,FALSE()) -> P1 | H7: =+VLOOKUP(B7,'transacciones '!$A$2:$I$39,7,FALSE()) -> Producción | I7: 0791 | J7: 0791 Extração de minério de ferro, inclusive beneficiamentos e a aglomeração | K7: B | L7: =+VLOOKUP(K7,'Correl CIIU'!$A$1:$F$26,2,FALSE()) -> Explotación de minas y canteras | M7: =+VLOOKUP(K7,'Correl CIIU'!$A$1:$F$26,3,FALSE()) -> Minería | N7: =+VLOOKUP(K7,'Correl CIIU'!$A$1:$F$26,4,FALSE()) -> Mining and quarrying | O7: 3 | P7: =+VLOOKUP(O7,bio!$A$2:$B$4,2,FALSE()) -> No bioeconomía
A8: BRAoc007 | B8: P10 | C8: =+VLOOKUP(B8,'transacciones '!$A$2:$I$39,2,FALSE()) -> ATC01 | D8: =+VLOOKUP(B8,'transacciones '!$A$2:$I$39,3,FALSE()) -> Producción / Consumo intermedio | E8: =+VLOOKUP(B8,'transacciones '!$A$2:$I$39,4,FALSE()) -> Producción | F8: =+VLOOKUP(B8,'transacciones '!$A$2:$I$39,5,FALSE()) -> 1 | G8: =+VLOOKUP(B8,'transacciones '!$A$2:$I$39,6,FALSE()) -> P1 | H8: =+VLOOKUP(B8,'transacciones '!$A$2:$I$39,7,FALSE()) -> Producción | I8: 0792 | J8: 0792 Extração de minerais metálicos não-ferrosos, inclusive beneficiamentos | K8: B | L8: =+VLOOKUP(K8,'Correl CIIU'!$A$1:$F$26,2,FALSE()) -> Explotación de minas y canteras | M8: =+VLOOKUP(K8,'Correl CIIU'!$A$1:$F$26,3,FALSE()) -> Minería | N8: =+VLOOKUP(K8,'Correl CIIU'!$A$1:$F$26,4,FALSE()) -> Mining and quarrying | O8: 3 | P8: =+VLOOKUP(O8,bio!$A$2:$B$4,2,FALSE()) -> No bioeconomía
A9: BRAoc008 | B9: P10 | C9: =+VLOOKUP(B9,'transacciones '!$A$2:$I$39,2,FALSE()) -> ATC01 | D9: =+VLOOKUP(B9,'transacciones '!$A$2:$I$39,3,FALSE()) -> Producción / Consumo intermedio | E9: =+VLOOKUP(B9,'transacciones '!$A$2:$I$39,4,FALSE()) -> Producción | F9: =+VLOOKUP(B9,'transacciones '!$A$2:$I$39,5,FALSE()) -> 1 | G9: =+VLOOKUP(B9,'transacciones '!$A$2:$I$39,6,FALSE()) -> P1 | H9: =+VLOOKUP(B9,'transacciones '!$A$2:$I$39,7,FALSE()) -> Producción | I9: 1091 | J9: 1091 Abate e produtos de carne, inclusive os produtos do laticínio e da pesca | K9: C | L9: =+VLOOKUP(K9,'Correl CIIU'!$A$1:$F$26,2,FALSE()) -> Industrias manufactureras | M9: =+VLOOKUP(K9,'Correl CIIU'!$A$1:$F$26,3,FALSE()) -> Manufacturas | N9: =+VLOOKUP(K9,'Correl CIIU'!$A$1:$F$26,4,FALSE()) -> Manufacturing | O9: 1 | P9: =+VLOOKUP(O9,bio!$A$2:$B$4,2,FALSE()) -> Bioeconomía
A10: BRAoc009 | B10: P10 | C10: =+VLOOKUP(B10,'transacciones '!$A$2:$I$39,2,FALSE()) -> ATC01 | D10: =+VLOOKUP(B10,'transacciones '!$A$2:$I$39,3,FALSE()) -> Producción / Consumo intermedio | E10: =+VLOOKUP(B10,'transacciones '!$A$2:$I$39,4,FALSE()) -> Producción | F10: =+VLOOKUP(B10,'transacciones '!$A$2:$I$39,5,FALSE()) -> 1 | G10: =+VLOOKUP(B10,'transacciones '!$A$2:$I$39,6,FALSE()) -> P1 | H10: =+VLOOKUP(B10,'transacciones '!$A$2:$I$39,7,FALSE()) -> Producción | I10: 1092 | J10: 1092 Fabricação e refino de açúcar | K10: C | L10: =+VLOOKUP(K10,'Correl CIIU'!$A$1:$F$26,2,FALSE()) -> Industrias manufactureras | M10: =+VLOOKUP(K10,'Correl CIIU'!$A$1:$F$26,3,FALSE()) -> Manufacturas | N10: =+VLOOKUP(K10,'Correl CIIU'!$A$1:$F$26,4,FALSE()) -> Manufacturing | O10: 1 | P10: =+VLOOKUP(O10,bio!$A$2:$B$4,2,FALSE()) -> Bioeconomía
A11: BRAoc010 | B11: P10 | C11: =+VLOOKUP(B11,'transacciones '!$A$2:$I$39,2,FALSE()) -> ATC01 | D11: =+VLOOKUP(B11,'transacciones '!$A$2:$I$39,3,FALSE()) -> Producción / Consumo intermedio | E11: =+VLOOKUP(B11,'transacciones '!$A$2:$I$39,4,FALSE()) -> Producción | F11: =+VLOOKUP(B11,'transacciones '!$A$2:$I$39,5,FALSE()) -> 1 | G11: =+VLOOKUP(B11,'transacciones '!$A$2:$I$39,6,FALSE()) -> P1 | H11: =+VLOOKUP(B11,'transacciones '!$A$2:$I$39,7,FALSE()) -> Producción | I11: 1093 | J11: 1093 Outros produtos alimentares | K11: C | L11: =+VLOOKUP(K11,'Correl CIIU'!$A$1:$F$26,2,FALSE()) -> Industrias manufactureras | M11: =+VLOOKUP(K11,'Correl CIIU'!$A$1:$F$26,3,FALSE()) -> Manufacturas | N11: =+VLOOKUP(K11,'Correl CIIU'!$A$1:$F$26,4,FALSE()) -> Manufacturing | O11: 1 | P11: =+VLOOKUP(O11,bio!$A$2:$B$4,2,FALSE()) -> Bioeconomía
A12: BRAoc011 | B12: P10 | C12: =+VLOOKUP(B12,'transacciones '!$A$2:$I$39,2,FALSE()) -> ATC01 | D12: =+VLOOKUP(B12,'transacciones '!$A$2:$I$39,3,FALSE()) -> Producción / Consumo intermedio | E12: =+VLOOKUP(B12,'transacciones '!$A$2:$I$39,4,FALSE()) -> Producción | F12: =+VLOOKUP(B12,'transacciones '!$A$2:$I$39,5,FALSE()) -> 1 | G12: =+VLOOKUP(B12,'transacciones '!$A$2:$I$39,6,FALSE()) -> P1 | H12: =+VLOOKUP(B12,'transacciones '!$A$2:$I$39,7,FALSE()) -> Producción | I12: 1100 | J12: 1100 Fabricação de bebidas | K12: C | L12: =+VLOOKUP(K12,'Correl CIIU'!$A$1:$F$26,2,FALSE()) -> Industrias manufactureras | M12: =+VLOOKUP(K12,'Correl CIIU'!$A$1:$F$26,3,FALSE()) -> Manufacturas | N12: =+VLOOKUP(K12,'Correl CIIU'!$A$1:$F$26,4,FALSE()) -> Manufacturing | O12: 1 | P12: =+VLOOKUP(O12,bio!$A$2:$B$4,2,FALSE()) -> Bioeconomía
A13: BRAoc012 | B13: P10 | C13: =+VLOOKUP(B13,'transacciones '!$A$2:$I$39,2,FALSE()) -> ATC01 | D13: =+VLOOKUP(B13,'transacciones '!$A$2:$I$39,3,FALSE()) -> Producción / Consumo intermedio | E13: =+VLOOKUP(B13,'transacciones '!$A$2:$I$39,4,FALSE()) -> Producción | F13: =+VLOOKUP(B13,'transacciones '!$A$2:$I$39,5,FALSE()) -> 1 | G13: =+VLOOKUP(B13,'transacciones '!$A$2:$I$39,6,FALSE()) -> P1 | H13: =+VLOOKUP(B13,'transacciones '!$A$2:$I$39,7,FALSE()) -> Producción | I13: 1200 | J13: 1200 Fabricação de produtos do fumo | K13: C | L13: =+VLOOKUP(K13,'Correl CIIU'!$A$1:$F$26,2,FALSE()) -> Industrias manufactureras | M13: =+VLOOKUP(K13,'Correl CIIU'!$A$1:$F$26,3,FALSE()) -> Manufacturas | N13: =+VLOOKUP(K13,'Correl CIIU'!$A$1:$F$26,4,FALSE()) -> Manufacturing | O13: 1 | P13: =+VLOOKUP(O13,bio!$A$2:$B$4,2,FALSE()) -> Bioeconomía
... A66: BRAoc065 | B66: P10 | C66: =+VLOOKUP(B66,'transacciones '!$A$2:$I$39,2,FALSE()) -> ATC01 | D66: =+VLOOKUP(B66,'transacciones '!$A$2:$I$39,3,FALSE()) -> Producción / Consumo intermedio | E66: =+VLOOKUP(B66,'transacciones '!$A$2:$I$39,4,FALSE()) -> Producción | F66: =+VLOOKUP(B66,'transacciones '!$A$2:$I$39,5,FALSE()) -> 1 | G66: =+VLOOKUP(B66,'transacciones '!$A$2:$I$39,6,FALSE()) -> P1 | H66: =+VLOOKUP(B66,'transacciones '!$A$2:$I$39,7,FALSE()) -> Producción | I66: 8692 | J66: 8692 Saúde privada | K66: Q | L66: =+VLOOKUP(K66,'Correl CIIU'!$A$1:$F$26,2,FALSE()) -> Actividades de atención de la salud humana y de asistencia social | M66: =+VLOOKUP(K66,'Correl CIIU'!$A$1:$F$26,3,FALSE()) -> Salud | N66: =+VLOOKUP(K66,'Correl CIIU'!$A$1:$F$26,4,FALSE()) -> Human health and social work activities | O66: 3 | P66: =+VLOOKUP(O66,bio!$A$2:$B$4,2,FALSE()) -> No bioeconomía
A67: BRAoc066 | B67: P10 | C67: =+VLOOKUP(B67,'transacciones '!$A$2:$I$39,2,FALSE()) -> ATC01 | D67: =+VLOOKUP(B67,'transacciones '!$A$2:$I$39,3,FALSE()) -> Producción / Consumo intermedio | E67: =+VLOOKUP(B67,'transacciones '!$A$2:$I$39,4,FALSE()) -> Producción | F67: =+VLOOKUP(B67,'transacciones '!$A$2:$I$39,5,FALSE()) -> 1 | G67: =+VLOOKUP(B67,'transacciones '!$A$2:$I$39,6,FALSE()) -> P1 | H67: =+VLOOKUP(B67,'transacciones '!$A$2:$I$39,7,FALSE()) -> Producción | I67: 9080 | J67: 9080 Atividades artísticas, criativas e de espetáculos | K67: R | L67: =+VLOOKUP(K67,'Correl CIIU'!$A$1:$F$26,2,FALSE()) -> Actividades artísticas, de entretenimiento y recreativas | M67: =+VLOOKUP(K67,'Correl CIIU'!$A$1:$F$26,3,FALSE()) -> Recreación | N67: =+VLOOKUP(K67,'Correl CIIU'!$A$1:$F$26,4,FALSE()) -> Arts, entertainment and recreation | O67: 3 | P67: =+VLOOKUP(O68,bio!$A$2:$B$4,2,FALSE()) -> No bioeconomía
A68: BRAoc067 | B68: P10 | C68: =+VLOOKUP(B68,'transacciones '!$A$2:$I$39,2,FALSE()) -> ATC01 | D68: =+VLOOKUP(B68,'transacciones '!$A$2:$I$39,3,FALSE()) -> Producción / Consumo intermedio | E68: =+VLOOKUP(B68,'transacciones '!$A$2:$I$39,4,FALSE()) -> Producción | F68: =+VLOOKUP(B68,'transacciones '!$A$2:$I$39,5,FALSE()) -> 1 | G68: =+VLOOKUP(B68,'transacciones '!$A$2:$I$39,6,FALSE()) -> P1 | H68: =+VLOOKUP(B68,'transacciones '!$A$2:$I$39,7,FALSE()) -> Producción | I68: 9480 | J68: 9480 Organizações associativas e outros serviços pessoais | K68: R | L68: =+VLOOKUP(K68,'Correl CIIU'!$A$1:$F$26,2,FALSE()) -> Actividades artísticas, de entretenimiento y recreativas | M68: =+VLOOKUP(K68,'Correl CIIU'!$A$1:$F$26,3,FALSE()) -> Recreación | N68: =+VLOOKUP(K68,'Correl CIIU'!$A$1:$F$26,4,FALSE()) -> Arts, entertainment and recreation | O68: 3 | P68: =+VLOOKUP(O69,bio!$A$2:$B$4,2,FALSE()) -> No bioeconomía
A69: BRAoc068 | B69: P10 | C69: =+VLOOKUP(B69,'transacciones '!$A$2:$I$39,2,FALSE()) -> ATC01 | D69: =+VLOOKUP(B69,'transacciones '!$A$2:$I$39,3,FALSE()) -> Producción / Consumo intermedio | E69: =+VLOOKUP(B69,'transacciones '!$A$2:$I$39,4,FALSE()) -> Producción | F69: =+VLOOKUP(B69,'transacciones '!$A$2:$I$39,5,FALSE()) -> 1 | G69: =+VLOOKUP(B69,'transacciones '!$A$2:$I$39,6,FALSE()) -> P1 | H69: =+VLOOKUP(B69,'transacciones '!$A$2:$I$39,7,FALSE()) -> Producción | I69: 9700 | J69: 9700 Serviços domésticos | K69: T | L69: =+VLOOKUP(K69,'Correl CIIU'!$A$1:$F$26,2,FALSE()) -> Actividades de los hogares como empleadores; actividades no diferenciadas de los hogares como productores de bienes y servicios para uso propio | M69: =+VLOOKUP(K69,'Correl CIIU'!$A$1:$F$26,3,FALSE()) -> Hogares como empleadores | N69: =+VLOOKUP(K69,'Correl CIIU'!$A$1:$F$26,4,FALSE()) -> Activities of households as employers; undifferentiated goods- and services-producing activities of households for own use | O69: 3 | P69: =+VLOOKUP(O69,bio!$A$2:$B$4,2,FALSE()) -> No bioeconomía
A70: BRAoc069 | I70: =LEFT(J70,4) -> Tota | J70: Total do produto
A71: BRAoc070 | B71: P70 | C71: =+VLOOKUP(B71,'transacciones '!$A$2:$I$39,2,FALSE()) -> ATC02 | D71: =+VLOOKUP(B71,'transacciones '!$A$2:$I$39,3,FALSE()) -> Exportaciones / Importaciones | E71: =+VLOOKUP(B71,'transacciones '!$A$2:$I$39,4,FALSE()) -> Importaciones de bienes Y SERVICIOS | F71: =+VLOOKUP(B71,'transacciones '!$A$2:$I$39,5,FALSE()) -> 0 | G71: =+VLOOKUP(B71,'transacciones '!$A$2:$I$39,6,FALSE()) -> P7 | H71: =+VLOOKUP(B71,'transacciones '!$A$2:$I$39,7,FALSE()) -> Importaciones de bienes y servicios | I71: =LEFT(J71,4) -> Impo | J71: Importação de bens e serviços (1) | K71: - | L71: - | M71: - | N71: - | O71: - | P71: -
A72: BRAoc071 | B72: M11 | C72: =+VLOOKUP(B72,'transacciones '!$A$2:$I$39,2,FALSE()) -> ATC05 | D72: =+VLOOKUP(B72,'transacciones '!$A$2:$I$39,3,FALSE()) -> Márgenes de distribución | E72: =+VLOOKUP(B72,'transacciones '!$A$2:$I$39,4,FALSE()) -> Márgenes de comercio | F72: =+VLOOKUP(B72,'transacciones '!$A$2:$I$39,5,FALSE()) -> 12 | G72: =+VLOOKUP(B72,'transacciones '!$A$2:$I$39,6,FALSE()) -> M1 | H72: =+VLOOKUP(B72,'transacciones '!$A$2:$I$39,7,FALSE()) -> Márgenes de distribución | I72: =LEFT(J72,4) -> Marg | J72: Margem de comércio | K72: - | L72: - | M72: - | N72: - | O72: - | P72: -
A73: BRAoc072 | B73: M12 | C73: =+VLOOKUP(B73,'transacciones '!$A$2:$I$39,2,FALSE()) -> ATC05 | D73: =+VLOOKUP(B73,'transacciones '!$A$2:$I$39,3,FALSE()) -> Márgenes de distribución | E73: =+VLOOKUP(B73,'transacciones '!$A$2:$I$39,4,FALSE()) -> Márgenes de transporte | F73: =+VLOOKUP(B73,'transacciones '!$A$2:$I$39,5,FALSE()) -> 12 | G73: =+VLOOKUP(B73,'transacciones '!$A$2:$I$39,6,FALSE()) -> M1 | H73: =+VLOOKUP(B73,'transacciones '!$A$2:$I$39,7,FALSE()) -> Márgenes de distribución | I73: =LEFT(J73,4) -> Marg | J73: Margem de transporte | K73: - | L73: - | M73: - | N73: - | O73: - | P73: -
A74: BRAoc073 | B74: D212 | C74: =+VLOOKUP(B74,'transacciones '!$A$2:$I$39,2,FALSE()) -> ATC04 | D74: =+VLOOKUP(B74,'transacciones '!$A$2:$I$39,3,FALSE()) -> Impuestos menos subvenciones sobre los productos | E74: =+VLOOKUP(B74,'transacciones '!$A$2:$I$39,4,FALSE()) -> Impuestos y derechos sobre las importaciones excepto IVA | F74: =+VLOOKUP(B74,'transacciones '!$A$2:$I$39,5,FALSE()) -> 9 | G74: =+VLOOKUP(B74,'transacciones '!$A$2:$I$39,6,FALSE()) -> D2 | H74: =+VLOOKUP(B74,'transacciones '!$A$2:$I$39,7,FALSE()) -> Impuestos sobre la producción y las importaciones | I74: =LEFT(J74,4) -> Impo | J74: Imposto de importação | K74: - | L74: - | M74: - | N74: - | O74: - | P74: -
A75: BRAoc074 | B75: D211 | C75: =+VLOOKUP(B75,'transacciones '!$A$2:$I$39,2,FALSE()) -> ATC04 | D75: =+VLOOKUP(B75,'transacciones '!$A$2:$I$39,3,FALSE()) -> Impuestos menos subvenciones sobre los productos | E75: =+VLOOKUP(B75,'transacciones '!$A$2:$I$39,4,FALSE()) -> Impuestos tipo valor agregado (IVA) | F75: =+VLOOKUP(B75,'transacciones '!$A$2:$I$39,5,FALSE()) -> 9 | G75: =+VLOOKUP(B75,'transacciones '!$A$2:$I$39,6,FALSE()) -> D2 | H75: =+VLOOKUP(B75,'transacciones '!$A$2:$I$39,7,FALSE()) -> Impuestos sobre la producción y las importaciones | I75: =LEFT(J75,4) -> IPI | J75: IPI | K75: - | L75: - | M75: - | N75: - | O75: - | P75: -
A76: BRAoc075 | B76: D214 | C76: =+VLOOKUP(B76,'transacciones '!$A$2:$I$39,2,FALSE()) -> ATC04 | D76: =+VLOOKUP(B76,'transacciones '!$A$2:$I$39,3,FALSE()) -> Impuestos menos subvenciones sobre los productos | E76: =+VLOOKUP(B76,'transacciones '!$A$2:$I$39,4,FALSE()) -> Impuestos sobre los productos, excepto IVA e impuestos sobre las importaciones | F76: =+VLOOKUP(B76,'transacciones '!$A$2:$I$39,5,FALSE()) -> 9 | G76: =+VLOOKUP(B76,'transacciones '!$A$2:$I$39,6,FALSE()) -> D2 | H76: =+VLOOKUP(B76,'transacciones '!$A$2:$I$39,7,FALSE()) -> Impuestos sobre la producción y las importaciones | I76: =LEFT(J76,4) -> ICMS | J76: ICMS | K76: - | L76: - | M76: - | N76: - | O76: - | P76: -
A77: BRAoc076 | B77: D214 | C77: =+VLOOKUP(B77,'transacciones '!$A$2:$I$39,2,FALSE()) -> ATC04 | D77: =+VLOOKUP(B77,'transacciones '!$A$2:$I$39,3,FALSE()) -> Impuestos menos subvenciones sobre los productos | E77: =+VLOOKUP(B77,'transacciones '!$A$2:$I$39,4,FALSE()) -> Impuestos sobre los productos, excepto IVA e impuestos sobre las importaciones | F77: =+VLOOKUP(B77,'transacciones '!$A$2:$I$39,5,FALSE()) -> 9 | G77: =+VLOOKUP(B77,'transacciones '!$A$2:$I$39,6,FALSE()) -> D2 | H77: =+VLOOKUP(B77,'transacciones '!$A$2:$I$39,7,FALSE()) -> Impuestos sobre la producción y las importaciones | I77: =LEFT(J77,4) -> Outr | J77: Outros impostos menos subsídios | K77: - | L77: - | M77: - | N77: - | O77: - | P77: -
A78: BRAoc077 | J78: Total de impostos líquidos de subsídios
A79: BRAuc001 | B79: P20 | C79: =+VLOOKUP(B79,'transacciones '!$A$2:$I$39,2,FALSE()) -> ATC01 | D79: =+VLOOKUP(B79,'transacciones '!$A$2:$I$39,3,FALSE()) -> Producción / Consumo intermedio | E79: =+VLOOKUP(B79,'transacciones '!$A$2:$I$39,4,FALSE()) -> Consumo | F79: =+VLOOKUP(B79,'transacciones '!$A$2:$I$39,5,FALSE()) -> 2 | G79: =+VLOOKUP(B79,'transacciones '!$A$2:$I$39,6,FALSE()) -> P2 | H79: =+VLOOKUP(B79,'transacciones '!$A$2:$I$39,7,FALSE()) -> Consumo intermedio | I79: 0191 | J79: 0191 Agricultura, inclusive o apoio à agricultura e a pós-colheita | K79: C | L79: =+VLOOKUP(K79,'Correl CIIU'!$A$1:$F$26,2,FALSE()) -> Industrias manufactureras | M79: =+VLOOKUP(K79,'Correl CIIU'!$A$1:$F$26,3,FALSE()) -> Manufacturas | N79: =+VLOOKUP(K79,'Correl CIIU'!$A$1:$F$26,4,FALSE()) -> Manufacturing | O79: 1 | P79: =+VLOOKUP(O79,bio!$A$2:$B$4,2,FALSE()) -> Bioeconomía
A80: BRAuc002 | B80: P20 | C80: =+VLOOKUP(B80,'transacciones '!$A$2:$I$39,2,FALSE()) -> ATC01 | D80: =+VLOOKUP(B80,'transacciones '!$A$2:$I$39,3,FALSE()) -> Producción / Consumo intermedio | E80: =+VLOOKUP(B80,'transacciones '!$A$2:$I$39,4,FALSE()) -> Consumo | F80: =+VLOOKUP(B80,'transacciones '!$A$2:$I$39,5,FALSE()) -> 2 | G80: =+VLOOKUP(B80,'transacciones '!$A$2:$I$39,6,FALSE()) -> P2 | H80: =+VLOOKUP(B80,'transacciones '!$A$2:$I$39,7,FALSE()) -> Consumo intermedio | I80: 0192 | J80: 0192 Pecuária, inclusive o apoio à pecuária | K80: A | L80: =+VLOOKUP(K80,'Correl CIIU'!$A$1:$F$26,2,FALSE()) -> Agricultura, ganadería, silvicultura y pesca | M80: =+VLOOKUP(K80,'Correl CIIU'!$A$1:$F$26,3,FALSE()) -> Agricultura | N80: =+VLOOKUP(K80,'Correl CIIU'!$A$1:$F$26,4,FALSE()) -> Agriculture, forestry and fishing | O80: 1 | P80: =+VLOOKUP(O80,bio!$A$2:$B$4,2,FALSE()) -> Bioeconomía
A81: BRAuc003 | B81: P20 | C81: =+VLOOKUP(B81,'transacciones '!$A$2:$I$39,2,FALSE()) -> ATC01 | D81: =+VLOOKUP(B81,'transacciones '!$A$2:$I$39,3,FALSE()) -> Producción / Consumo intermedio | E81: =+VLOOKUP(B81,'transacciones '!$A$2:$I$39,4,FALSE()) -> Consumo | F81: =+VLOOKUP(B81,'transacciones '!$A$2:$I$39,5,FALSE()) -> 2 | G81: =+VLOOKUP(B81,'transacciones '!$A$2:$I$39,6,FALSE()) -> P2 | H81: =+VLOOKUP(B81,'transacciones '!$A$2:$I$39,7,FALSE()) -> Consumo intermedio | I81: 0280 | J81: 0280 Produção florestal; pesca e aquicultura | K81: A | L81: =+VLOOKUP(K81,'Correl CIIU'!$A$1:$F$26,2,FALSE()) -> Agricultura, ganadería, silvicultura y pesca | M81: =+VLOOKUP(K81,'Correl CIIU'!$A$1:$F$26,3,FALSE()) -> Agricultura | N81: =+VLOOKUP(K81,'Correl CIIU'!$A$1:$F$26,4,FALSE()) -> Agriculture, forestry and fishing | O81: 1 | P81: =+VLOOKUP(O81,bio!$A$2:$B$4,2,FALSE()) -> Bioeconomía
A82: BRAuc004 | B82: P20 | C82: =+VLOOKUP(B82,'transacciones '!$A$2:$I$39,2,FALSE()) -> ATC01 | D82: =+VLOOKUP(B82,'transacciones '!$A$2:$I$39,3,FALSE()) -> Producción / Consumo intermedio | E82: =+VLOOKUP(B82,'transacciones '!$A$2:$I$39,4,FALSE()) -> Consumo | F82: =+VLOOKUP(B82,'transacciones '!$A$2:$I$39,5,FALSE()) -> 2 | G82: =+VLOOKUP(B82,'transacciones '!$A$2:$I$39,6,FALSE()) -> P2 | H82: =+VLOOKUP(B82,'transacciones '!$A$2:$I$39,7,FALSE()) -> Consumo intermedio | I82: 0580 | J82: 0580 Extração de carvão mineral e de minerais não-metálicos | K82: B | L82: =+VLOOKUP(K82,'Correl CIIU'!$A$1:$F$26,2,FALSE()) -> Explotación de minas y canteras | M82: =+VLOOKUP(K82,'Correl CIIU'!$A$1:$F$26,3,FALSE()) -> Minería | N82: =+VLOOKUP(K82,'Correl CIIU'!$A$1:$F$26,4,FALSE()) -> Mining and quarrying | O82: 3 | P82: =+VLOOKUP(O82,bio!$A$2:$B$4,2,FALSE()) -> No bioeconomía
A83: BRAuc005 | B83: P20 | C83: =+VLOOKUP(B83,'transacciones '!$A$2:$I$39,2,FALSE()) -> ATC01 | D83: =+VLOOKUP(B83,'transacciones '!$A$2:$I$39,3,FALSE()) -> Producción / Consumo intermedio | E83: =+VLOOKUP(B83,'transacciones '!$A$2:$I$39,4,FALSE()) -> Consumo | F83: =+VLOOKUP(B83,'transacciones '!$A$2:$I$39,5,FALSE()) -> 2 | G83: =+VLOOKUP(B83,'transacciones '!$A$2:$I$39,6,FALSE()) -> P2 | H83: =+VLOOKUP(B83,'transacciones '!$A$2:$I$39,7,FALSE()) -> Consumo intermedio | I83: 0680 | J83: 0680 Extração de petróleo e gás, inclusive as atividades de apoio | K83: B | L83: =+VLOOKUP(K83,'Correl CIIU'!$A$1:$F$26,2,FALSE()) -> Explotación de minas y canteras | M83: =+VLOOKUP(K83,'Correl CIIU'!$A$1:$F$26,3,FALSE()) -> Minería | N83: =+VLOOKUP(K83,'Correl CIIU'!$A$1:$F$26,4,FALSE()) -> Mining and quarrying | O83: 3 | P83: =+VLOOKUP(O83,bio!$A$2:$B$4,2,FALSE()) -> No bioeconomía
A84: BRAuc006 | B84: P20 | C84: =+VLOOKUP(B84,'transacciones '!$A$2:$I$39,2,FALSE()) -> ATC01 | D84: =+VLOOKUP(B84,'transacciones '!$A$2:$I$39,3,FALSE()) -> Producción / Consumo intermedio | E84: =+VLOOKUP(B84,'transacciones '!$A$2:$I$39,4,FALSE()) -> Consumo | F84: =+VLOOKUP(B84,'transacciones '!$A$2:$I$39,5,FALSE()) -> 2 | G84: =+VLOOKUP(B84,'transacciones '!$A$2:$I$39,6,FALSE()) -> P2 | H84: =+VLOOKUP(B84,'transacciones '!$A$2:$I$39,7,FALSE()) -> Consumo intermedio | I84: 0791 | J84: 0791 Extração de minério de ferro, inclusive beneficiamentos e a aglomeração | K84: B | L84: =+VLOOKUP(K84,'Correl CIIU'!$A$1:$F$26,2,FALSE()) -> Explotación de minas y canteras | M84: =+VLOOKUP(K84,'Correl CIIU'!$A$1:$F$26,3,FALSE()) -> Minería | N84: =+VLOOKUP(K84,'Correl CIIU'!$A$1:$F$26,4,FALSE()) -> Mining and quarrying | O84: 3 | P84: =+VLOOKUP(O84,bio!$A$2:$B$4,2,FALSE()) -> No bioeconomía
A85: BRAuc007 | B85: P20 | C85: =+VLOOKUP(B85,'transacciones '!$A$2:$I$39,2,FALSE()) -> ATC01 | D85: =+VLOOKUP(B85,'transacciones '!$A$2:$I$39,3,FALSE()) -> Producción / Consumo intermedio | E85: =+VLOOKUP(B85,'transacciones '!$A$2:$I$39,4,FALSE()) -> Consumo | F85: =+VLOOKUP(B85,'transacciones '!$A$2:$I$39,5,FALSE()) -> 2 | G85: =+VLOOKUP(B85,'transacciones '!$A$2:$I$39,6,FALSE()) -> P2 | H85: =+VLOOKUP(B85,'transacciones '!$A$2:$I$39,7,FALSE()) -> Consumo intermedio | I85: 0792 | J85: 0792 Extração de minerais metálicos não-ferrosos, inclusive beneficiamentos | K85: B | L85: =+VLOOKUP(K85,'Correl CIIU'!$A$1:$F$26,2,FALSE()) -> Explotación de minas y canteras | M85: =+VLOOKUP(K85,'Correl CIIU'!$A$1:$F$26,3,FALSE()) -> Minería | N85: =+VLOOKUP(K85,'Correl CIIU'!$A$1:$F$26,4,FALSE()) -> Mining and quarrying | O85: 3 | P85: =+VLOOKUP(O85,bio!$A$2:$B$4,2,FALSE()) -> No bioeconomía
A86: BRAuc008 | B86: P20 | C86: =+VLOOKUP(B86,'transacciones '!$A$2:$I$39,2,FALSE()) -> ATC01 | D86: =+VLOOKUP(B86,'transacciones '!$A$2:$I$39,3,FALSE()) -> Producción / Consumo intermedio | E86: =+VLOOKUP(B86,'transacciones '!$A$2:$I$39,4,FALSE()) -> Consumo | F86: =+VLOOKUP(B86,'transacciones '!$A$2:$I$39,5,FALSE()) -> 2 | G86: =+VLOOKUP(B86,'transacciones '!$A$2:$I$39,6,FALSE()) -> P2 | H86: =+VLOOKUP(B86,'transacciones '!$A$2:$I$39,7,FALSE()) -> Consumo intermedio | I86: 1091 | J86: 1091 Abate e produtos de carne, inclusive os produtos do laticínio e da pesca | K86: C | L86: =+VLOOKUP(K86,'Correl CIIU'!$A$1:$F$26,2,FALSE()) -> Industrias manufactureras | M86: =+VLOOKUP(K86,'Correl CIIU'!$A$1:$F$26,3,FALSE()) -> Manufacturas | N86: =+VLOOKUP(K86,'Correl CIIU'!$A$1:$F$26,4,FALSE()) -> Manufacturing | O86: 1 | P86: =+VLOOKUP(O86,bio!$A$2:$B$4,2,FALSE()) -> Bioeconomía
A87: BRAuc009 | B87: P20 | C87: =+VLOOKUP(B87,'transacciones '!$A$2:$I$39,2,FALSE()) -> ATC01 | D87: =+VLOOKUP(B87,'transacciones '!$A$2:$I$39,3,FALSE()) -> Producción / Consumo intermedio | E87: =+VLOOKUP(B87,'transacciones '!$A$2:$I$39,4,FALSE()) -> Consumo | F87: =+VLOOKUP(B87,'transacciones '!$A$2:$I$39,5,FALSE()) -> 2 | G87: =+VLOOKUP(B87,'transacciones '!$A$2:$I$39,6,FALSE()) -> P2 | H87: =+VLOOKUP(B87,'transacciones '!$A$2:$I$39,7,FALSE()) -> Consumo intermedio | I87: 1092 | J87: 1092 Fabricação e refino de açúcar | K87: C | L87: =+VLOOKUP(K87,'Correl CIIU'!$A$1:$F$26,2,FALSE()) -> Industrias manufactureras | M87: =+VLOOKUP(K87,'Correl CIIU'!$A$1:$F$26,3,FALSE()) -> Manufacturas | N87: =+VLOOKUP(K87,'Correl CIIU'!$A$1:$F$26,4,FALSE()) -> Manufacturing | O87: 1 | P87: =+VLOOKUP(O87,bio!$A$2:$B$4,2,FALSE()) -> Bioeconomía
A88: BRAuc010 | B88: P20 | C88: =+VLOOKUP(B88,'transacciones '!$A$2:$I$39,2,FALSE()) -> ATC01 | D88: =+VLOOKUP(B88,'transacciones '!$A$2:$I$39,3,FALSE()) -> Producción / Consumo intermedio | E88: =+VLOOKUP(B88,'transacciones '!$A$2:$I$39,4,FALSE()) -> Consumo | F88: =+VLOOKUP(B88,'transacciones '!$A$2:$I$39,5,FALSE()) -> 2 | G88: =+VLOOKUP(B88,'transacciones '!$A$2:$I$39,6,FALSE()) -> P2 | H88: =+VLOOKUP(B88,'transacciones '!$A$2:$I$39,7,FALSE()) -> Consumo intermedio | I88: 1093 | J88: 1093 Outros produtos alimentares | K88: C | L88: =+VLOOKUP(K88,'Correl CIIU'!$A$1:$F$26,2,FALSE()) -> Industrias manufactureras | M88: =+VLOOKUP(K88,'Correl CIIU'!$A$1:$F$26,3,FALSE()) -> Manufacturas | N88: =+VLOOKUP(K88,'Correl CIIU'!$A$1:$F$26,4,FALSE()) -> Manufacturing | O88: 1 | P88: =+VLOOKUP(O88,bio!$A$2:$B$4,2,FALSE()) -> Bioeconomía
A89: BRAuc011 | B89: P20 | C89: =+VLOOKUP(B89,'transacciones '!$A$2:$I$39,2,FALSE()) -> ATC01 | D89: =+VLOOKUP(B89,'transacciones '!$A$2:$I$39,3,FALSE()) -> Producción / Consumo intermedio | E89: =+VLOOKUP(B89,'transacciones '!$A$2:$I$39,4,FALSE()) -> Consumo | F89: =+VLOOKUP(B89,'transacciones '!$A$2:$I$39,5,FALSE()) -> 2 | G89: =+VLOOKUP(B89,'transacciones '!$A$2:$I$39,6,FALSE()) -> P2 | H89: =+VLOOKUP(B89,'transacciones '!$A$2:$I$39,7,FALSE()) -> Consumo intermedio | I89: 1100 | J89: 1100 Fabricação de bebidas | K89: C | L89: =+VLOOKUP(K89,'Correl CIIU'!$A$1:$F$26,2,FALSE()) -> Industrias manufactureras | M89: =+VLOOKUP(K89,'Correl CIIU'!$A$1:$F$26,3,FALSE()) -> Manufacturas | N89: =+VLOOKUP(K89,'Correl CIIU'!$A$1:$F$26,4,FALSE()) -> Manufacturing | O89: 1 | P89: =+VLOOKUP(O89,bio!$A$2:$B$4,2,FALSE()) -> Bioeconomía
A90: BRAuc012 | B90: P20 | C90: =+VLOOKUP(B90,'transacciones '!$A$2:$I$39,2,FALSE()) -> ATC01 | D90: =+VLOOKUP(B90,'transacciones '!$A$2:$I$39,3,FALSE()) -> Producción / Consumo intermedio | E90: =+VLOOKUP(B90,'transacciones '!$A$2:$I$39,4,FALSE()) -> Consumo | F90: =+VLOOKUP(B90,'transacciones '!$A$2:$I$39,5,FALSE()) -> 2 | G90: =+VLOOKUP(B90,'transacciones '!$A$2:$I$39,6,FALSE()) -> P2 | H90: =+VLOOKUP(B90,'transacciones '!$A$2:$I$39,7,FALSE()) -> Consumo intermedio | I90: 1200 | J90: 1200 Fabricação de produtos do fumo | K90: C | L90: =+VLOOKUP(K90,'Correl CIIU'!$A$1:$F$26,2,FALSE()) -> Industrias manufactureras | M90: =+VLOOKUP(K90,'Correl CIIU'!$A$1:$F$26,3,FALSE()) -> Manufacturas | N90: =+VLOOKUP(K90,'Correl CIIU'!$A$1:$F$26,4,FALSE()) -> Manufacturing | O90: 1 | P90: =+VLOOKUP(O90,bio!$A$2:$B$4,2,FALSE()) -> Bioeconomía
... A143: BRAuc065 | B143: P20 | C143: =+VLOOKUP(B143,'transacciones '!$A$2:$I$39,2,FALSE()) -> ATC01 | D143: =+VLOOKUP(B143,'transacciones '!$A$2:$I$39,3,FALSE()) -> Producción / Consumo intermedio | E143: =+VLOOKUP(B143,'transacciones '!$A$2:$I$39,4,FALSE()) -> Consumo | F143: =+VLOOKUP(B143,'transacciones '!$A$2:$I$39,5,FALSE()) -> 2 | G143: =+VLOOKUP(B143,'transacciones '!$A$2:$I$39,6,FALSE()) -> P2 | H143: =+VLOOKUP(B143,'transacciones '!$A$2:$I$39,7,FALSE()) -> Consumo intermedio | I143: 8692 | J143: 8692 Saúde privada | K143: Q | L143: =+VLOOKUP(K143,'Correl CIIU'!$A$1:$F$26,2,FALSE()) -> Actividades de atención de la salud humana y de asistencia social | M143: =+VLOOKUP(K143,'Correl CIIU'!$A$1:$F$26,3,FALSE()) -> Salud | N143: =+VLOOKUP(K143,'Correl CIIU'!$A$1:$F$26,4,FALSE()) -> Human health and social work activities | O143: 3 | P143: =+VLOOKUP(O143,bio!$A$2:$B$4,2,FALSE()) -> No bioeconomía
A144: BRAuc066 | B144: P20 | C144: =+VLOOKUP(B144,'transacciones '!$A$2:$I$39,2,FALSE()) -> ATC01 | D144: =+VLOOKUP(B144,'transacciones '!$A$2:$I$39,3,FALSE()) -> Producción / Consumo intermedio | E144: =+VLOOKUP(B144,'transacciones '!$A$2:$I$39,4,FALSE()) -> Consumo | F144: =+VLOOKUP(B144,'transacciones '!$A$2:$I$39,5,FALSE()) -> 2 | G144: =+VLOOKUP(B144,'transacciones '!$A$2:$I$39,6,FALSE()) -> P2 | H144: =+VLOOKUP(B144,'transacciones '!$A$2:$I$39,7,FALSE()) -> Consumo intermedio | I144: 9080 | J144: 9080 Atividades artísticas, criativas e de espetáculos | K144: R | L144: =+VLOOKUP(K144,'Correl CIIU'!$A$1:$F$26,2,FALSE()) -> Actividades artísticas, de entretenimiento y recreativas | M144: =+VLOOKUP(K144,'Correl CIIU'!$A$1:$F$26,3,FALSE()) -> Recreación | N144: =+VLOOKUP(K144,'Correl CIIU'!$A$1:$F$26,4,FALSE()) -> Arts, entertainment and recreation | O144: 3 | P144: =+VLOOKUP(O145,bio!$A$2:$B$4,2,FALSE()) -> No bioeconomía
...

Sheet Correl CIIU
A1: CIIU Secciones | B1: CIIU Secciones descripción | C1: CIIU Corto | D1: CIIU English
A2: A | B2: Agricultura, ganadería, silvicultura y pesca | C2: Agricultura | D2: Agriculture, forestry and fishing
A3: B | B3: Explotación de minas y canteras | C3: Minería | D3: Mining and quarrying
A4: C | B4: Industrias manufactureras | C4: Manufacturas | D4: Manufacturing
A5: C | B5: Industrias manufactureras | C5: Manufacturas | D5: Manufacturing
A6: C | B6: Industrias manufactureras | C6: Manufacturas | D6: Manufacturing
A7: D | B7: Suministro de electricidad, gas, vapor y aire acondicionado | C7: Servicios básicos | D7: Electricity, gas, steam and air conditioning supply
A8: E | B8: Suministro de agua; evacuación de aguas residuales, gestión de desechos y descontaminación | C8: Suministro de agua | D8: Water supply; sewerage, waste management and remediation activities
A9: F | B9: Construcción | C9: Construcción | D9: Construction
A10: G | B10: Comercio al por mayor y al por menor; reparación de vehículos automotores y motocicletas | C10: Comercio | D10: Wholesale and retail trade; repair of motor vehicles and motorcycles
A11: H | B11: Transporte y almacenamiento | C11: Transporte y almacenamiento | D11: Transportation and storage
A12: J | B12: Información y comunicaciones | C12: Información y comunicaciones | D12: Information and communication
... A26: - | B26: - | C26: - | D26: -

Sheet transacciones 
A1: Código Transacciones | B1: Área transaccional columnas No. | C1: Área transaccional | D1: Transacciones | E1: Correlativo Transacciones Agregadas | F1: Código Transacciones Agregadas | G1: Transacciones Agregadas | H1: corr_ntg2 | I1: id_area_columnas
A2: P10 | B2: ATC01 | C2: Producción / Consumo intermedio | D2: Producción | E2: 1 | F2: P1 | G2: Producción | H2: 1 | I2: 0
A3: P11 | B3: ATC01 | C3: Producción / Consumo intermedio | D3: Producción de mercado | E3: 1 | F3: P1 | G3: Producción | H3: 2 | I3: 1
A4: P12 | B4: ATC01 | C4: Producción / Consumo intermedio | D4: Producción para uso final propio | E4: 1 | F4: P1 | G4: Producción | H4: 3 | I4: 2
A5: P13 | B5: ATC01 | C5: Producción / Consumo intermedio | D5: Otra producción no de mercado | E5: 1 | F5: P1 | G5: Producción | H5: 4 | I5: 3
A6: P20 | B6: ATC01 | C6: Producción / Consumo intermedio | D6: Consumo | E6: 2 | F6: P2 | G6: Consumo intermedio | H6: 5 | I6: 0
A7: P21 | B7: ATC01 | C7: Producción / Consumo intermedio | D7: Consumo intermedio de mercado | E7: 2 | F7: P2 | G7: Consumo intermedio | H7: 6 | I7: 1
A8: P22 | B8: ATC01 | C8: Producción / Consumo intermedio | D8: Consumo intermedio para uso final propio | E8: 2 | F8: P2 | G8: Consumo intermedio | H8: 7 | I8: 2
A9: P23 | B9: ATC01 | C9: Producción / Consumo intermedio | D9: Consumo intermedio no de mercado | E9: 2 | F9: P2 | G9: Consumo intermedio | H9: 8 | I9: 3
A10: Pa31 | B10: ATC06 | C10: Gasto de consumo final | D10: Gasto de consumo final de los hogares | E10: 3 | F10: P3 | G10: Gasto de consumo final | H10: 9 | I10: 9
A11: Pb30 | B11: ATC06 | C11: Consumo final | D11: Gasto de consumo ISFLH | E11: 3 | F11: P3 | G11: Gasto de consumo final | H11: 10 | I11: 9
A12: Pb31 | B12: ATC06 | C12: Consumo final | D12: Gasto de consumo individual ISFLSH | E12: 3 | F12: P3 | G12: Gasto de consumo final | H12: 11 | I12: 9
A13: Pb32 | B13: ATC06 | C13: Consumo final | D13: Gasto de consumo colectivo ISFLSH | E13: 3 | F13: P3 | G13: Gasto de consumo final | H13: 12 | I13: 9
A14: Pc30 | B14: ATC06 | C14: Consumo final | D14: Gasto de consumo de gobierno | E14: 3 | F14: P3 | G14: Gasto de consumo final
A15: Pc31 | B15: ATC06 | C15: Consumo final | D15: Gasto de consumo individual de gobierno | E15: 3 | F15: P3 | G15: Gasto de consumo final | H15: 13 | I15: 9
A16: Pc32 | B16: ATC06 | C16: Consumo final | D16: Gasto de consumo colectivo de gobierno | E16: 3 | F16: P3 | G16: Gasto de consumo final | H16: 14 | I16: 9
A17: P41 | B17: ATC06 | C17: Consumo final | D17: Consumo individual efectivo | E17: 4 | F17: P4 | G17: Consumo final efectivo | H17: 15 | I17: 9
A18: P42 | B18: ATC06 | C18: Consumo final | D18: Consumo colectivo efectivo | E18: 4 | F18: P4 | G18: Consumo final efectivo | H18: 16 | I18: 9
A19: P51b | B19: ATC07 | C19: Consumo final | D19: Formación bruta de capital fijo | E19: 5 | F19: P5 | G19: Formación de capital | H19: 17 | I19: 10
A20: P51c | B20: ATC07 | C20: Consumo final | D20: Consumo de capital fijo | E20: 5 | F20: P5 | G20: Formación de capital | H20: 18 | I20: 10
A21: P52 | B21: ATC07 | C21: Consumo final | D21: Variación de existencias | E21: 5 | F21: P5 | G21: Formación de capital | H21: 19 | I21: 10
A22: P53 | B22: ATC07 | C22: Consumo final | D22: Adquisiciones menos disposiciones de objetos valiosos | E22: 5 | F22: P5 | G22: Formación de capital | H22: 20 | I22: 10
A23: P60 | B23: ATC02 | C23: Exportaciones / Importaciones | D23: Exportaciones de bienes y servicios | E23: 6 | F23: P6 | G23: Exportaciones de bienes y servicios | H23: 21 | I23: 4
A24: P61 | B24: ATC02 | C24: Exportaciones / Importaciones | D24: Exportaciones de bienes | E24: 6 | F24: P6 | G24: Exportaciones de bienes y servicios | H24: 22 | I24: 4
A25: P62 | B25: ATC02 | C25: Exportaciones / Importaciones | D25: Exportaciones de servicios | E25: 6 | F25: P6 | G25: Exportaciones de bienes y servicios | H25: 23 | I25: 4
A26: P70 | B26: ATC02 | C26: Exportaciones / Importaciones | D26: Importaciones de bienes Y SERVICIOS | F26: P7 | G26: Importaciones de bienes y servicios | H26: 24 | I26: 4
A27: P71 | B27: ATC02 | C27: Exportaciones / Importaciones | D27: Importaciones de bienes | E27: 7 | F27: P7 | G27: Importaciones de bienes y servicios | H27: 25 | I27: 4
A28: P72 | B28: ATC02 | C28: Exportaciones / Importaciones | D28: Importaciones de servicios | E28: 7 | F28: P7 | G28: Importaciones de bienes y servicios | H28: 26 | I28: 4
A29: CIF | B29: ATC03 | C29: Ajuste CIF/FOB | D29: Ajuste CIF/FOB sobre importaciones | E29: 8 | F29: CIF | G29: Ajuste CIF/FOB sobre importaciones | H29: 27 | I29: 5
A30: D211 | B30: ATC04 | C30: Impuestos menos subvenciones sobre los productos | D30: Impuestos tipo valor agregado (IVA) | E30: 9 | F30: D2 | G30: Impuestos sobre la producción y las importaciones | H30: 28 | I30: 6
A31: D212 | B31: ATC04 | C31: Impuestos menos subvenciones sobre los productos | D31: Impuestos y derechos sobre las importaciones excepto IVA | E31: 9 | F31: D2 | G31: Impuestos sobre la producción y las importaciones | H31: 29 | I31: 6
A32: D213 | B32: ATC04 | C32: Impuestos menos subvenciones sobre los productos | D32: Impuestos sobre las exportaciones | E32: 9 | F32: D2 | G32: Impuestos sobre la producción y las importaciones | H32: 30 | I32: 6
A33: D214 | B33: ATC04 | C33: Impuestos menos subvenciones sobre los productos | D33: Impuestos sobre los productos, excepto IVA e impuestos sobre las importaciones | E33: 9 | F33: D2 | G33: Impuestos sobre la producción y las importaciones | H33: 31 | I33: 6
A34: D291 | B34: ATC04 | C34: Impuestos menos subvenciones sobre los productos | D34: Otros impuestos sobre la producción | E34: 10 | F34: D29 | G34: Otros impuestos sobre la producción | H34: 32 | I34: 6
A35: D31 | B35: ATC04 | C35: Impuestos menos subvenciones sobre los productos | D35: Subvenciones a los productos | E35: 11 | F35: D3 | G35: Subvenciones | H35: 33 | I35: 7
A36: D39 | B36: ATCO4 | C36: Impuestos menos subvenciones sobre los productos | D36: Otras subvenciones a la producción | E36: 11 | F36: D3 | G36: Subvenciones | H36: 34 | I36: 7
A37: M11 | B37: ATC05 | C37: Márgenes de distribución | D37: Márgenes de comercio | E37: 12 | F37: M1 | G37: Márgenes de distribución | H37: 35 | I37: 8
A38: M12 | B38: ATC05 | C38: Márgenes de distribución | D38: Márgenes de transporte | E38: 12 | F38: M1 | G38: Márgenes de distribución | H38: 36 | I38: 8
A39: M13 | B39: ATC05 | C39: Márgenes de distribución | D39: Márgenes de distribución de electricidad | E39: 12 | F39: M1 | G39: Márgenes de distribución | H39: 37 | I39: 8

Sheet bio
A1: Correlativo Bioeconomía Productos | B1: Bioeconomía Productos | D1: Correlativo Bioeconomía Actividades | E1: Bioeconomía Actividades
A2: 1 | B2: Bioeconomía | D2: 1 | E2: Bioeconomía
A3: 2 | B3: Bioeconomía extendida | D3: 2 | E3: Bioeconomía extendida
A4: 3 | B4: No bioeconomía | D4: 3 | E4: No bioeconomía

Sheet at_columnas
A1: Área transaccional columnas No. | B1: Área transaccional | C1: Código Transacciones | D1: Detalle Transacciones
A2: ATC01 | B2: Producción / Consumo intermedio | C2: P11 | D2: Producción de mercado
A3: ATC01 | B3: Producción / Consumo intermedio | C3: P12 | D3: Producción para uso final propio
A4: ATC01 | B4: Producción / Consumo intermedio | C4: P13 | D4: Producción no de mercado
A5: ATC01 | B5: Producción / Consumo intermedio | C5: P21 | D5: Consumo intermedio de mercado
A6: ATC01 | B6: Producción / Consumo intermedio | C6: P22 | D6: Consumo intermedio para uso final propio
A7: ATC01 | B7: Producción / Consumo intermedio | C7: P23 | D7: Consumo intermedio no de mercado
A8: ATC02 | B8: Exportaciones / Importaciones | C8: P6 | D8: Total Exportaciones
A9: ATC02 | B9: Exportaciones / Importaciones | C9: P61 | D9: Exportación de bienes
A10: ATC02 | B10: Exportaciones / Importaciones | C10: P62 | D10: Exportación de servicios
A11: ATC02 | B11: Exportaciones / Importaciones | C11: P7 | D11: Importación de bienes
A12: ATC02 | B12: Exportaciones / Importaciones | C12: P7 | D12: Importación de servicios
... A23: ATC07 | B23: Formación bruta de capital | C23: P52 | D23: Variación de existencias

Sheet filas
A1: Filas | B1: Áreas Transaccionales Filas No. | C1: Áreas Transaccionales Filas Descripción | D1: Codigo Transacción Filas | E1: Código Nomenclatura Local de Productos | F1: Nomenclatura Local de Productos | G1: Clasificación Productos | H1: Cod_Bioec Productos | I1: Tipo de bioeconomía Productos | J1: Sectores produuctos | K1: Cód_Div_CPC_3 | L1: División CPC_3 | M1: Cód_Div_CPC_2 | N1: División CPC_2 | O1: Cod. Elem. Def. Bioeconomía | P1: Tipo de elemento | Q1: Código CPC | R1: Elemento CPC | S1: Código Bioeconomía | T1: Clasificación Bioeconomí
A2: BRAof001 | B2: ATF01 | C2: =VLOOKUP(B2, AT_FILAS!$A$2:$C$8,2,FALSE()) -> Producción | D2: =VLOOKUP(B2, AT_FILAS!$A$2:$C$8,3,FALSE()) -> P1 | E2: 01911 | F2: Arroz, trigo e outros cereais | G2: Productos agricolas_Cereales | H2: 1 | I2: Bioeconomía de productos básicos | J2: Productos agropecuarios | K2: 1 | L2: =VLOOKUP(K2,clasif_filas!$A$1:$J$39,2,FALSE()) -> Productos de la agricultura, la horticultura y la jardinería comercial | M2: =VLOOKUP(K2,clasif_filas!$A$1:$J$39,3,FALSE()) -> 1 | N2: =VLOOKUP(K2,clasif_filas!$A$1:$J$39,4,FALSE()) -> Productos de la agricultura, la horticultura y la jardinería comercial | O2: =VLOOKUP(K2,clasif_filas!$A$1:$J$39,5,FALSE()) -> 1 | P2: =VLOOKUP(K2,clasif_filas!$A$1:$J$39,6,FALSE()) -> Biomasa que se cultiva para producir alimentos, forrajes, fibras y energía | Q2: =VLOOKUP(K2,clasif_filas!$A$1:$J$39,7,FALSE()) -> 0 | R2: =VLOOKUP(K2,clasif_filas!$A$1:$J$39,8,FALSE()) -> Productos de la agricultura, la silvicultura yla pesca | S2: =VLOOKUP(K2,clasif_filas!$A$1:$J$39,9,FALSE()) -> 1 | T2: =VLOOKUP(K2,clasif_filas!$A$1:$J$39,10,FALSE()) -> Bioeconomía
A3: BRAof002 | B3: ATF01 | C3: =VLOOKUP(B3, AT_FILAS!$A$2:$C$8,2,FALSE()) -> Producción | D3: =VLOOKUP(B3, AT_FILAS!$A$2:$C$8,3,FALSE()) -> P1 | E3: 01912 | F3: Milho em grão | G3: Productos agricolas_Cereales | H3: 1 | I3: Bioeconomía de productos básicos | J3: Productos agropecuarios | K3: 1 | L3: =VLOOKUP(K3,clasif_filas!$A$1:$J$39,2,FALSE()) -> Productos de la agricultura, la horticultura y la jardinería comercial | M3: =VLOOKUP(K3,clasif_filas!$A$1:$J$39,3,FALSE()) -> 1 | N3: =VLOOKUP(K3,clasif_filas!$A$1:$J$39,4,FALSE()) -> Productos de la agricultura, la horticultura y la jardinería comercial | O3: =VLOOKUP(K3,clasif_filas!$A$1:$J$39,5,FALSE()) -> 1 | P3: =VLOOKUP(K3,clasif_filas!$A$1:$J$39,6,FALSE()) -> Biomasa que se cultiva para producir alimentos, forrajes, fibras y energía | Q3: =VLOOKUP(K3,clasif_filas!$A$1:$J$39,7,FALSE()) -> 0 | R3: =VLOOKUP(K3,clasif_filas!$A$1:$J$39,8,FALSE()) -> Productos de la agricultura, la silvicultura yla pesca | S3: =VLOOKUP(K3,clasif_filas!$A$1:$J$39,9,FALSE()) -> 1 | T3: =VLOOKUP(K3,clasif_filas!$A$1:$J$39,10,FALSE()) -> Bioeconomía
A4: BRAof003 | B4: ATF01 | C4: =VLOOKUP(B4, AT_FILAS!$A$2:$C$8,2,FALSE()) -> Producción | D4: =VLOOKUP(B4, AT_FILAS!$A$2:$C$8,3,FALSE()) -> P1 | E4: 01913 | F4: Algodão herbáceo, outras fibras da lav. temporária | G4: Productos agricolas_Oleaginosas | H4: 1 | I4: Bioeconomía de productos básicos | J4: Productos agropecuarios | K4: 1 | L4: =VLOOKUP(K4,clasif_filas!$A$1:$J$39,2,FALSE()) -> Productos de la agricultura, la horticultura y la jardinería comercial | M4: =VLOOKUP(K4,clasif_filas!$A$1:$J$39,3,FALSE()) -> 1 | N4: =VLOOKUP(K4,clasif_filas!$A$1:$J$39,4,FALSE()) -> Productos de la agricultura, la horticultura y la jardinería comercial | O4: =VLOOKUP(K4,clasif_filas!$A$1:$J$39,5,FALSE()) -> 1 | P4: =VLOOKUP(K4,clasif_filas!$A$1:$J$39,6,FALSE()) -> Biomasa que se cultiva para producir alimentos, forrajes, fibras y energía | Q4: =VLOOKUP(K4,clasif_filas!$A$1:$J$39,7,FALSE()) -> 0 | R4: =VLOOKUP(K4,clasif_filas!$A$1:$J$39,8,FALSE()) -> Productos de la agricultura, la silvicultura yla pesca | S4: =VLOOKUP(K4,clasif_filas!$A$1:$J$39,9,FALSE()) -> 1 | T4: =VLOOKUP(K4,clasif_filas!$A$1:$J$39,10,FALSE()) -> Bioeconomía
A5: BRAof004 | B5: ATF01 | C5: =VLOOKUP(B5, AT_FILAS!$A$2:$C$8,2,FALSE()) -> Producción | D5: =VLOOKUP(B5, AT_FILAS!$A$2:$C$8,3,FALSE()) -> P1 | E5: 01914 | F5: Cana-de-açúcar | G5: Productos agricolas_Azúcar | H5: 1 | I5: Bioeconomía de productos básicos | J5: Productos agropecuarios | K5: 1 | L5: =VLOOKUP(K5,clasif_filas!$A$1:$J$39,2,FALSE()) -> Productos de la agricultura, la horticultura y la jardinería comercial | M5: =VLOOKUP(K5,clasif_filas!$A$1:$J$39,3,FALSE()) -> 1 | N5: =VLOOKUP(K5,clasif_filas!$A$1:$J$39,4,FALSE()) -> Productos de la agricultura, la horticultura y la jardinería comercial | O5: =VLOOKUP(K5,clasif_filas!$A$1:$J$39,5,FALSE()) -> 1 | P5: =VLOOKUP(K5,clasif_filas!$A$1:$J$39,6,FALSE()) -> Biomasa que se cultiva para producir alimentos, forrajes, fibras y energía | Q5: =VLOOKUP(K5,clasif_filas!$A$1:$J$39,7,FALSE()) -> 0 | R5: =VLOOKUP(K5,clasif_filas!$A$1:$J$39,8,FALSE()) -> Productos de la agricultura, la silvicultura yla pesca | S5: =VLOOKUP(K5,clasif_filas!$A$1:$J$39,9,FALSE()) -> 1 | T5: =VLOOKUP(K5,clasif_filas!$A$1:$J$39,10,FALSE()) -> Bioeconomía
A6: BRAof005 | B6: ATF01 | C6: =VLOOKUP(B6, AT_FILAS!$A$2:$C$8,2,FALSE()) -> Producción | D6: =VLOOKUP(B6, AT_FILAS!$A$2:$C$8,3,FALSE()) -> P1 | E6: 01915 | F6: Soja em grão | G6: Productos agricolas_Oleaginosas | H6: 1 | I6: Bioeconomía de productos básicos | J6: Productos agropecuarios | K6: 1 | L6: =VLOOKUP(K6,clasif_filas!$A$1:$J$39,2,FALSE()) -> Productos de la agricultura, la horticultura y la jardinería comercial | M6: =VLOOKUP(K6,clasif_filas!$A$1:$J$39,3,FALSE()) -> 1 | N6: =VLOOKUP(K6,clasif_filas!$A$1:$J$39,4,FALSE()) -> Productos de la agricultura, la horticultura y la jardinería comercial | O6: =VLOOKUP(K6,clasif_filas!$A$1:$J$39,5,FALSE()) -> 1 | P6: =VLOOKUP(K6,clasif_filas!$A$1:$J$39,6,FALSE()) -> Biomasa que se cultiva para producir alimentos, forrajes, fibras y energía | Q6: =VLOOKUP(K6,clasif_filas!$A$1:$J$39,7,FALSE()) -> 0 | R6: =VLOOKUP(K6,clasif_filas!$A$1:$J$39,8,FALSE()) -> Productos de la agricultura, la silvicultura yla pesca | S6: =VLOOKUP(K6,clasif_filas!$A$1:$J$39,9,FALSE()) -> 1 | T6: =VLOOKUP(K6,clasif_filas!$A$1:$J$39,10,FALSE()) -> Bioeconomía
A7: BRAof006 | B7: ATF01 | C7: =VLOOKUP(B7, AT_FILAS!$A$2:$C$8,2,FALSE()) -> Producción | D7: =VLOOKUP(B7, AT_FILAS!$A$2:$C$8,3,FALSE()) -> P1 | E7: 01916 | F7: Outros produtos e serviços da lavoura temporária | G7: Productos alimentarios_Otros | H7: 1 | I7: Bioeconomía de productos básicos | J7: Productos agropecuarios | K7: 1 | L7: =VLOOKUP(K7,clasif_filas!$A$1:$J$39,2,FALSE()) -> Productos de la agricultura, la horticultura y la jardinería comercial | M7: =VLOOKUP(K7,clasif_filas!$A$1:$J$39,3,FALSE()) -> 1 | N7: =VLOOKUP(K7,clasif_filas!$A$1:$J$39,4,FALSE()) -> Productos de la agricultura, la horticultura y la jardinería comercial | O7: =VLOOKUP(K7,clasif_filas!$A$1:$J$39,5,FALSE()) -> 1 | P7: =VLOOKUP(K7,clasif_filas!$A$1:$J$39,6,FALSE()) -> Biomasa que se cultiva para producir alimentos, forrajes, fibras y energía | Q7: =VLOOKUP(K7,clasif_filas!$A$1:$J$39,7,FALSE()) -> 0 | R7: =VLOOKUP(K7,clasif_filas!$A$1:$J$39,8,FALSE()) -> Productos de la agricultura, la silvicultura yla pesca | S7: =VLOOKUP(K7,clasif_filas!$A$1:$J$39,9,FALSE()) -> 1 | T7: =VLOOKUP(K7,clasif_filas!$A$1:$J$39,10,FALSE()) -> Bioeconomía
A8: BRAof007 | B8: ATF01 | C8: =VLOOKUP(B8, AT_FILAS!$A$2:$C$8,2,FALSE()) -> Producción | D8: =VLOOKUP(B8, AT_FILAS!$A$2:$C$8,3,FALSE()) -> P1 | E8: 01917 | F8: Laranja | G8: Productos agricolas_Frutas | H8: 1 | I8: Bioeconomía de productos básicos | J8: Productos agropecuarios | K8: 1 | L8: =VLOOKUP(K8,clasif_filas!$A$1:$J$39,2,FALSE()) -> Productos de la agricultura, la horticultura y la jardinería comercial | M8: =VLOOKUP(K8,clasif_filas!$A$1:$J$39,3,FALSE()) -> 1 | N8: =VLOOKUP(K8,clasif_filas!$A$1:$J$39,4,FALSE()) -> Productos de la agricultura, la horticultura y la jardinería comercial | O8: =VLOOKUP(K8,clasif_filas!$A$1:$J$39,5,FALSE()) -> 1 | P8: =VLOOKUP(K8,clasif_filas!$A$1:$J$39,6,FALSE()) -> Biomasa que se cultiva para producir alimentos, forrajes, fibras y energía | Q8: =VLOOKUP(K8,clasif_filas!$A$1:$J$39,7,FALSE()) -> 0 | R8: =VLOOKUP(K8,clasif_filas!$A$1:$J$39,8,FALSE()) -> Productos de la agricultura, la silvicultura yla pesca | S8: =VLOOKUP(K8,clasif_filas!$A$1:$J$39,9,FALSE()) -> 1 | T8: =VLOOKUP(K8,clasif_filas!$A$1:$J$39,10,FALSE()) -> Bioeconomía
A9: BRAof008 | B9: ATF01 | C9: =VLOOKUP(B9, AT_FILAS!$A$2:$C$8,2,FALSE()) -> Producción | D9: =VLOOKUP(B9, AT_FILAS!$A$2:$C$8,3,FALSE()) -> P1 | E9: 01918 | F9: Café em grão | G9: Productos agricolas_Café y te | H9: 1 | I9: Bioeconomía de productos básicos | J9: Productos agropecuarios | K9: 1 | L9: =VLOOKUP(K9,clasif_filas!$A$1:$J$39,2,FALSE()) -> Productos de la agricultura, la horticultura y la jardinería comercial | M9: =VLOOKUP(K9,clasif_filas!$A$1:$J$39,3,FALSE()) -> 1 | N9: =VLOOKUP(K9,clasif_filas!$A$1:$J$39,4,FALSE()) -> Productos de la agricultura, la horticultura y la jardinería comercial | O9: =VLOOKUP(K9,clasif_filas!$A$1:$J$39,5,FALSE()) -> 1 | P9: =VLOOKUP(K9,clasif_filas!$A$1:$J$39,6,FALSE()) -> Biomasa que se cultiva para producir alimentos, forrajes, fibras y energía | Q9: =VLOOKUP(K9,clasif_filas!$A$1:$J$39,7,FALSE()) -> 0 | R9: =VLOOKUP(K9,clasif_filas!$A$1:$J$39,8,FALSE()) -> Productos de la agricultura, la silvicultura yla pesca | S9: =VLOOKUP(K9,clasif_filas!$A$1:$J$39,9,FALSE()) -> 1 | T9: =VLOOKUP(K9,clasif_filas!$A$1:$J$39,10,FALSE()) -> Bioeconomía
A10: BRAof009 | B10: ATF01 | C10: =VLOOKUP(B10, AT_FILAS!$A$2:$C$8,2,FALSE()) -> Producción | D10: =VLOOKUP(B10, AT_FILAS!$A$2:$C$8,3,FALSE()) -> P1 | E10: 01919 | F10: Outros produtos da lavoura permanente | G10: Productos agricolas_Otros | H10: 1 | I10: Bioeconomía de productos básicos | J10: Industria alimentaria | K10: 1 | L10: =VLOOKUP(K10,clasif_filas!$A$1:$J$39,2,FALSE()) -> Productos de la agricultura, la horticultura y la jardinería comercial | M10: =VLOOKUP(K10,clasif_filas!$A$1:$J$39,3,FALSE()) -> 1 | N10: =VLOOKUP(K10,clasif_filas!$A$1:$J$39,4,FALSE()) -> Productos de la agricultura, la horticultura y la jardinería comercial | O10: =VLOOKUP(K10,clasif_filas!$A$1:$J$39,5,FALSE()) -> 1 | P10: =VLOOKUP(K10,clasif_filas!$A$1:$J$39,6,FALSE()) -> Biomasa que se cultiva para producir alimentos, forrajes, fibras y energía | Q10: =VLOOKUP(K10,clasif_filas!$A$1:$J$39,7,FALSE()) -> 0 | R10: =VLOOKUP(K10,clasif_filas!$A$1:$J$39,8,FALSE()) -> Productos de la agricultura, la silvicultura yla pesca | S10: =VLOOKUP(K10,clasif_filas!$A$1:$J$39,9,FALSE()) -> 1 | T10: =VLOOKUP(K10,clasif_filas!$A$1:$J$39,10,FALSE()) -> Bioeconomía
A11: BRAof010 | B11: ATF01 | C11: =VLOOKUP(B11, AT_FILAS!$A$2:$C$8,2,FALSE()) -> Producción | D11: =VLOOKUP(B11, AT_FILAS!$A$2:$C$8,3,FALSE()) -> P1 | E11: 01921 | F11: Bovinos e outros animais vivos, prods. animal, caça e serv. | G11: Animales y plantas | H11: 1 | I11: Bioeconomía de productos básicos | J11: Productos agropecuarios | K11: 2 | L11: =VLOOKUP(K11,clasif_filas!$A$1:$J$39,2,FALSE()) -> Animales vivos y productos animales (excepto la carne) | M11: =VLOOKUP(K11,clasif_filas!$A$1:$J$39,3,FALSE()) -> 2 | N11: =VLOOKUP(K11,clasif_filas!$A$1:$J$39,4,FALSE()) -> Animales vivos y productos animales (excepto la carne) | O11: =VLOOKUP(K11,clasif_filas!$A$1:$J$39,5,FALSE()) -> 1 | P11: =VLOOKUP(K11,clasif_filas!$A$1:$J$39,6,FALSE()) -> Biomasa que se cultiva para producir alimentos, forrajes, fibras y energía | Q11: =VLOOKUP(K11,clasif_filas!$A$1:$J$39,7,FALSE()) -> 0 | R11: =VLOOKUP(K11,clasif_filas!$A$1:$J$39,8,FALSE()) -> Productos de la agricultura, la silvicultura yla pesca | S11: =VLOOKUP(K11,clasif_filas!$A$1:$J$39,9,FALSE()) -> 1 | T11: =VLOOKUP(K11,clasif_filas!$A$1:$J$39,10,FALSE()) -> Bioeconomía
A12: BRAof011 | B12: ATF01 | C12: =VLOOKUP(B12, AT_FILAS!$A$2:$C$8,2,FALSE()) -> Producción | D12: =VLOOKUP(B12, AT_FILAS!$A$2:$C$8,3,FALSE()) -> P1 | E12: 01922 | F12: Leite de vaca e de outros animais | G12: Productos agricolas_Lácteos | H12: 1 | I12: Bioeconomía de productos básicos | J12: Productos agropecuarios | K12: 2 | L12: =VLOOKUP(K12,clasif_filas!$A$1:$J$39,2,FALSE()) -> Animales vivos y productos animales (excepto la carne) | M12: =VLOOKUP(K12,clasif_filas!$A$1:$J$39,3,FALSE()) -> 2 | N12: =VLOOKUP(K12,clasif_filas!$A$1:$J$39,4,FALSE()) -> Animales vivos y productos animales (excepto la carne) | O12: =VLOOKUP(K12,clasif_filas!$A$1:$J$39,5,FALSE()) -> 1 | P12: =VLOOKUP(K12,clasif_filas!$A$1:$J$39,6,FALSE()) -> Biomasa que se cultiva para producir alimentos, forrajes, fibras y energía | Q12: =VLOOKUP(K12,clasif_filas!$A$1:$J$39,7,FALSE()) -> 0 | R12: =VLOOKUP(K12,clasif_filas!$A$1:$J$39,8,FALSE()) -> Productos de la agricultura, la silvicultura yla pesca | S12: =VLOOKUP(K12,clasif_filas!$A$1:$J$39,9,FALSE()) -> 1 | T12: =VLOOKUP(K12,clasif_filas!$A$1:$J$39,10,FALSE()) -> Bioeconomía
A13: BRAof012 | B13: ATF01 | C13: =VLOOKUP(B13, AT_FILAS!$A$2:$C$8,2,FALSE()) -> Producción | D13: =VLOOKUP(B13, AT_FILAS!$A$2:$C$8,3,FALSE()) -> P1 | E13: 01923 | F13: Suínos | G13: Animales y plantas | H13: 1 | I13: Bioeconomía de productos básicos | J13: Productos agropecuarios | K13: 2 | L13: =VLOOKUP(K13,clasif_filas!$A$1:$J$39,2,FALSE()) -> Animales vivos y productos animales (excepto la carne) | M13: =VLOOKUP(K13,clasif_filas!$A$1:$J$39,3,FALSE()) -> 2 | N13: =VLOOKUP(K13,clasif_filas!$A$1:$J$39,4,FALSE()) -> Animales vivos y productos animales (excepto la carne) | O13: =VLOOKUP(K13,clasif_filas!$A$1:$J$39,5,FALSE()) -> 1 | P13: =VLOOKUP(K13,clasif_filas!$A$1:$J$39,6,FALSE()) -> Biomasa que se cultiva para producir alimentos, forrajes, fibras y energía | Q13: =VLOOKUP(K13,clasif_filas!$A$1:$J$39,7,FALSE()) -> 0 | R13: =VLOOKUP(K13,clasif_filas!$A$1:$J$39,8,FALSE()) -> Productos de la agricultura, la silvicultura yla pesca | S13: =VLOOKUP(K13,clasif_filas!$A$1:$J$39,9,FALSE()) -> 1 | T13: =VLOOKUP(K13,clasif_filas!$A$1:$J$39,10,FALSE()) -> Bioeconomía
... A69: BRAof068 | B69: ATF01 | C69: =VLOOKUP(B69, AT_FILAS!$A$2:$C$8,2,FALSE()) -> Producción | D69: =VLOOKUP(B69, AT_FILAS!$A$2:$C$8,3,FALSE()) -> P1 | E69: 24912 | F69: Semi-acabacados, laminados planos, longos e tubos de aço | G69: No bioeconomía | H69: 4 | I69: No bioeconomía | J69: No bioeconomía | K69: 38 | L69: =VLOOKUP(K69,clasif_filas!$A$1:$J$39,2,FALSE()) -> Muebles; otros bienes transportables n.c.p. | M69: =VLOOKUP(K69,clasif_filas!$A$1:$J$39,3,FALSE()) -> 38 | N69: =VLOOKUP(K69,clasif_filas!$A$1:$J$39,4,FALSE()) -> Muebles; otros bienes transportables n.c.p. | O69: =VLOOKUP(K69,clasif_filas!$A$1:$J$39,5,FALSE()) -> 99 | P69: =VLOOKUP(K69,clasif_filas!$A$1:$J$39,6,FALSE()) -> No Bioeconomía | Q69: =VLOOKUP(K69,clasif_filas!$A$1:$J$39,7,FALSE()) -> 3 | R69: =VLOOKUP(K69,clasif_filas!$A$1:$J$39,8,FALSE()) -> Otros bienes transportables, excepto productos metálicos, maquinaria y equipo | S69: =VLOOKUP(K69,clasif_filas!$A$1:$J$39,9,FALSE()) -> 3 | T69: =VLOOKUP(K69,clasif_filas!$A$1:$J$39,10,FALSE()) -> No bioeconomía
